Workbook

Sheet 시간표
B1: 개인 | D1: 합창 | F1: 단체 | H1: 심화
A3: 1 | B3: ='24년'!#REF! -> #REF! | C3: ='24년'!#REF! -> #REF! | D3: ='24년'!#REF! -> #REF! | E3: ='24년'!#REF! -> #REF! | F3: ='24년'!B39 -> 고영숙 | G3: ='24년'!#REF! -> #REF! | H3: ='24년'!#REF! -> #REF! | I3: ='24년'!#REF! -> #REF!
A4: 2 | B4: ='24년'!#REF! -> #REF! | C4: ='24년'!#REF! -> #REF! | D4: ='24년'!#REF! -> #REF! | E4: ='24년'!#REF! -> #REF! | F4: ='24년'!B41 -> 김용 | G4: ='24년'!#REF! -> #REF! | H4: ='24년'!#REF! -> #REF! | I4: ='24년'!#REF! -> #REF!
A5: 3 | B5: ='24년'!B13 -> 임하린 | C5: ='24년'!#REF! -> #REF! | D5: ='24년'!#REF! -> #REF! | E5: ='24년'!#REF! -> #REF! | F5: ='24년'!B43 -> 윤분숙 | G5: ='24년'!#REF! -> #REF! | H5: ='24년'!B50 -> 임하린 | I5: ='24년'!#REF! -> #REF!
A6: 4 | B6: ='24년'!B14 -> 배이준 | C6: ='24년'!#REF! -> #REF! | D6: ='24년'!#REF! -> #REF! | E6: ='24년'!#REF! -> #REF! | F6: ='24년'!B44 -> 석경남 | G6: ='24년'!#REF! -> #REF! | H6: ='24년'!#REF! -> #REF! | I6: ='24년'!#REF! -> #REF!
A7: 5 | B7: ='24년'!B15 -> 변이서 | C7: ='24년'!#REF! -> #REF! | D7: ='24년'!#REF! -> #REF! | E7: ='24년'!#REF! -> #REF! | F7: ='24년'!#REF! -> #REF! | G7: ='24년'!#REF! -> #REF! | H7: ='24년'!#REF! -> #REF! | I7: ='24년'!#REF! -> #REF!
A8: 6 | B8: ='24년'!#REF! -> #REF! | C8: ='24년'!#REF! -> #REF! | D8: ='24년'!#REF! -> #REF! | E8: ='24년'!#REF! -> #REF! | F8: ='24년'!B45 -> 박상혜 | G8: ='24년'!#REF! -> #REF! | H8: ='24년'!#REF! -> #REF! | I8: ='24년'!#REF! -> #REF!
A9: 7 | B9: ='24년'!#REF! -> #REF! | C9: ='24년'!#REF! -> #REF! | D9: ='24년'!#REF! -> #REF! | E9: ='24년'!#REF! -> #REF! | F9: ='24년'!#REF! -> #REF! | G9: ='24년'!#REF! -> #REF! | H9: ='24년'!#REF! -> #REF! | I9: ='24년'!#REF! -> #REF!
A10: 8 | B10: ='24년'!#REF! -> #REF! | C10: ='24년'!#REF! -> #REF! | D10: ='24년'!#REF! -> #REF! | E10: ='24년'!#REF! -> #REF! | F10: ='24년'!#REF! -> #REF! | G10: ='24년'!#REF! -> #REF!
A11: 9 | B11: ='24년'!#REF! -> #REF! | C11: ='24년'!#REF! -> #REF! | D11: ='24년'!#REF! -> #REF! | E11: ='24년'!#REF! -> #REF!
A12: 10 | B12: ='24년'!#REF! -> #REF! | C12: ='24년'!#REF! -> #REF! | D12: ='24년'!#REF! -> #REF! | E12: ='24년'!#REF! -> #REF!
A13: 11 | B13: ='24년'!B16 -> 문도진 | C13: ='24년'!#REF! -> #REF! | D13: ='24년'!#REF! -> #REF! | E13: ='24년'!#REF! -> #REF!
A14: 12 | B14: ='24년'!B17 -> 박지윤 | C14: ='24년'!#REF! -> #REF! | D14: ='24년'!#REF! -> #REF! | E14: ='24년'!#REF! -> #REF!
A15: 13 | B15: ='24년'!#REF! -> #REF! | C15: ='24년'!#REF! -> #REF!
A16: 14 | B16: ='24년'!#REF! -> #REF! | C16: ='24년'!#REF! -> #REF!

Sheet 24년1월
A1: 민요개인 | C1: 민요단체 | D1: ; | E1: 장구단체 | F1: ] | H1: 1주차
A2: 우리인력 | B2: =COUNTIF(I:AL,"우리인력") -> 8 | C2: 고영숙 | D2: =COUNTIF(I:AL,"고영숙;") -> 7 | E2: 고영숙 | F2: =COUNTIF(I:AL,"고영숙]") -> 0 | I2: 1 | K2: 2 | M2: 3 | O2: 4 | Q2: 5 | S2: 6 | U2: 7
A3: 김혜숙 | B3: =COUNTIF(I:AL,"김혜숙") -> 9 | C3: 공하정 | D3: =COUNTIF(I:AL,"공하정;") -> 4 | E3: 공하정 | F3: =COUNTIF(I:AL,"공하정]") -> 0 | I3: 월 | K3: 화 | M3: 수 | O3: 목 | Q3: 금 | S3: 토 | U3: 일
A4: 배이준 | B4: =COUNTIF(I:AL,"배이준") -> 4 | C4: 김다정 | D4: =COUNTIF(I:AL,"김다정;") -> 0 | E4: 이소영 | F4: =COUNTIF(I:AL,"이소영]") -> 0 | H4: 10 | K4: 우리인력 | O4: 우리인력
A5: 신하린 | B5: =COUNTIF(I:AL,"신하린") -> 2 | C5: 김용 | D5: =COUNTIF(I:AL,"김용;") -> 4 | E5: 임하린 | F5: =COUNTIF(I:AL,"임하린]") -> 0
A6: 아름다움 | B6: =COUNTIF(I:AL,"아름다움") -> 7 | C6: 윤분숙 | D6: =COUNTIF(I:AL,"윤분숙;") -> 0 | H6: 11 | K6: 김혜숙 | O6: 김혜숙 | S6: 배이준
A7: 이기찬 | B7: =COUNTIF(I:AL,"이기찬") -> 5 | C7: 이말진 | D7: =COUNTIF(I:AL,"이말진;") -> 3
A8: 초빈초연 | B8: =COUNTIF(I:AL,"초빈초연") -> 6 | C8: 최임이 | D8: =COUNTIF(I:AL,"최임이;") -> 2 | H8: 12
A9: 이소영 | B9: =COUNTIF(I:AL,"이소영") -> 1 | C9: 김혜정 | D9: =COUNTIF(I:AL,"김혜정;") -> 1
A10: 임하령 | B10: =COUNTIF(I:AL,"임하령") -> 2 | C10: 임하린 | D10: =COUNTIF(K:AN,"임하린;") -> 2 | H10: 1
A11: 임하린 | B11: =COUNTIF(I:AL,"임하린") -> 4 | C11: 정지원 | D11: =COUNTIF(K:AN,"정지원;") -> 2
A12: 정지원 | B12: =COUNTIF(I:AL,"정지원") -> 3 | C12: 초빈초연 | D12: =COUNTIF(K:AN,"초빈초연;") -> 4 | H12: 2 | K12: 이기찬 | O12: 이기찬
A13: 최은실 | B13: =COUNTIF(I:AL,"최은실") -> 2 | C13: 아름다움 | D13: =COUNTIF(K:AN,"아름다움;") -> 3
A14: 박창민 | B14: =COUNTIF(I:AL,"박창민") -> 0 | C14: 박창민 | D14: =COUNTIF(K:AN,"박창민;") -> 0 | H14: 3 | K14: 이소영 | M14: 김용; | N14: 공하정;
A15: 채린 | B15: =COUNTIF(I:AL,"채린") -> 0 | C15: 배이준 | D15: =COUNTIF(K:AN,"배이준;") -> 3 | M15: 고영숙;
A16: 최임이 | B16: =COUNTIF(I:AL,"최임이") -> 0 | C16: 임하령 | D16: =COUNTIF(K:AN,"임하령;") -> 0 | H16: 4 | K16: 임하린
A17: 김혜정 | B17: =COUNTIF(I:AL,"김혜정") -> 1 | C17: 이소영 | D17: =COUNTIF(K:AN,"이소영;") -> 1
C18: 이기찬 | D18: =COUNTIF(K:AN,"이기찬;") -> 1 | H18: 5 | K18: 임하령 | M18: 신하린 | O18: 초빈초연 | U18: 아름다움
C19: 채린 | D19: =COUNTIF(K:AN,"채린;") -> 0
H20: 6 | K20: 초빈초연; | L20: 배이준; | M20: 이말진; | N20: 고영숙;
K21: 이소영; | L21: 임하린;
K22: 이기찬;
H24: 7
A28: 민요개인 | C28: 민요단체 | D28: ; | E28: 장구단체 | F28: ] | H28: 2주차
A29: 우리인력 | B29: =COUNTIF(I:AL,"우리인력") -> 8 | C29: 고영숙 | D29: =COUNTIF(I:AL,"고영숙;") -> 7 | E29: 고영숙 | F29: =COUNTIF(I:AL,"고영숙]") -> 0 | I29: 8 | K29: 9 | M29: 10 | O29: 11 | Q29: 12 | S29: 13 | U29: 14
A30: 김혜숙 | B30: =COUNTIF(I:AL,"김혜숙") -> 9 | C30: 공하정 | D30: =COUNTIF(I:AL,"공하정;") -> 4 | E30: 공하정 | F30: =COUNTIF(I:AL,"공하정]") -> 0 | I30: 월 | K30: 화 | M30: 수 | O30: 목 | Q30: 금 | S30: 토 | U30: 일
A31: 배이준 | B31: =COUNTIF(I:AL,"배이준") -> 4 | C31: 김다정 | D31: =COUNTIF(I:AL,"김다정;") -> 0 | E31: 이소영 | F31: =COUNTIF(I:AL,"이소영]") -> 0 | H31: 10 | I31: 우리인력 | O31: 우리인력
A32: 신하린 | B32: =COUNTIF(I:AL,"신하린") -> 2 | C32: 김용 | D32: =COUNTIF(I:AL,"김용;") -> 4 | E32: 임하린 | F32: =COUNTIF(I:AL,"임하린]") -> 0
A33: 아름다움 | B33: =COUNTIF(I:AL,"아름다움") -> 7 | C33: 윤분숙 | D33: =COUNTIF(I:AL,"윤분숙;") -> 0 | H33: 11 | K33: 김혜숙 | O33: 김혜숙 | S33: 배이준
A34: 이기찬 | B34: =COUNTIF(I:AL,"이기찬") -> 5 | C34: 이말직 | D34: =COUNTIF(I:AL,"이말직;") -> 0
A35: 초빈초연 | B35: =COUNTIF(I:AL,"초빈초연") -> 6 | C35: 최임이 | D35: =COUNTIF(I:AL,"최임이;") -> 2 | H35: 12 | Q35: 이기찬
A36: 이소영 | B36: =COUNTIF(I:AL,"이소영") -> 1 | C36: 김혜정 | D36: =COUNTIF(I:AL,"김혜정;") -> 1
A37: 임하령 | B37: =COUNTIF(I:AL,"임하령") -> 2 | C37: 임하린 | D37: =COUNTIF(K:AN,"임하린;") -> 2 | H37: 1
A38: 임하린 | B38: =COUNTIF(I:AL,"임하린") -> 4 | C38: 정지원 | D38: =COUNTIF(K:AN,"정지원;") -> 2
A39: 정지원 | B39: =COUNTIF(I:AL,"정지원") -> 3 | C39: 초빈초연 | D39: =COUNTIF(K:AN,"초빈초연;") -> 4 | H39: 2
A40: 최은실 | B40: =COUNTIF(I:AL,"최은실") -> 2 | C40: 아름다움 | D40: =COUNTIF(K:AN,"아름다움;") -> 3
A41: 박창민 | B41: =COUNTIF(I:AL,"박창민") -> 0 | C41: 박창민 | D41: =COUNTIF(K:AN,"박창민;") -> 0 | H41: 3 | K41: 임하린 | M41: 김용; | N41: 공하정;
A42: 채린 | B42: =COUNTIF(I:AL,"채린") -> 0 | C42: 배이준 | D42: =COUNTIF(K:AN,"배이준;") -> 3 | M42: 고영숙;
A43: 최임이 | B43: =COUNTIF(I:AL,"최임이") -> 0 | C43: 임하령 | D43: =COUNTIF(K:AN,"임하령;") -> 0 | H43: 4 | K43: 아름다움 | O43: 정지원
A44: 김혜정 | B44: =COUNTIF(I:AL,"김혜정") -> 1 | C44: 이소영 | D44: =COUNTIF(K:AN,"이소영;") -> 1
...

Sheet 24년2월
A1: 민요개인 | C1: 민요단체 | D1: ; | E1: 장구단체 | F1: ] | H1: 1주차
A2: 우리인력 | B2: =COUNTIF(I:AL,"우리인력") -> 5 | C2: 고영숙 | D2: =COUNTIF(I:AL,"고영숙;") -> 5 | E2: 고영숙 | F2: =COUNTIF(I:AL,"고영숙]") -> 0 | I2: 1 | K2: 2 | M2: 3 | O2: 4 | Q2: 5 | S2: 6 | U2: 7 | W2: 11
A3: 김혜숙 | B3: =COUNTIF(I:AL,"김혜숙") -> 0 | C3: 공하정 | D3: =COUNTIF(I:AL,"공하정;") -> 1 | E3: 공하정 | F3: =COUNTIF(I:AL,"공하정]") -> 0 | I3: 목 | K3: 금 | M3: 토 | O3: 일 | Q3: 월 | S3: 화 | U3: 수 | W3: 일
A4: 배이준 | B4: =COUNTIF(I:AL,"배이준") -> 3 | C4: 김다정 | D4: =COUNTIF(I:AL,"김다정;") -> 0 | E4: 소영하린 | F4: =COUNTIF(I:AL,"소영하린]") -> 2 | H4: 10 | I4: 우리인력
A5: 신하린 | B5: =COUNTIF(I:AL,"신하린") -> 2 | C5: 김용 | D5: =COUNTIF(I:AL,"김용;") -> 3
A6: 아름다움 | B6: =COUNTIF(I:AL,"아름다움") -> 0 | C6: 윤분숙 | D6: =COUNTIF(I:AL,"윤분숙;") -> 4 | H6: 11 | K6: 이기찬
A7: 이기찬 | B7: =COUNTIF(I:AL,"이기찬") -> 3 | C7: 이말진 | D7: =COUNTIF(I:AL,"이말진;") -> 0
A8: 초연 | B8: =COUNTIF(I:AL,"초연") -> 0 | C8: 최임이 | D8: =COUNTIF(I:AL,"최임이;") -> 3 | H8: 12 | M8: 배이준
A9: 이소영 | B9: =COUNTIF(I:AL,"이소영") -> 5 | C9: 김혜정 | D9: =COUNTIF(I:AL,"김혜정;") -> 0
A10: 임하령 | B10: =COUNTIF(I:AL,"임하령") -> 0 | H10: 1
A11: 임하린 | B11: =COUNTIF(I:AL,"임하린") -> 4 | C11: 임하린 | D11: =COUNTIF(K:AN,"임하린;") -> 3
A12: 정지원 | B12: =COUNTIF(I:AL,"정지원") -> 3 | C12: 정지원 | D12: =COUNTIF(K:AN,"정지원;") -> 3 | H12: 2 | I12: 임하린
A13: 최은실 | B13: =COUNTIF(I:AL,"최은실") -> 0 | C13: 초연 | D13: =COUNTIF(K:AN,"초연;") -> 0
A14: 박창민 | B14: =COUNTIF(I:AL,"박창민") -> 0 | C14: 아름다움 | D14: =COUNTIF(K:AN,"아름다움;") -> 0 | H14: 3 | Q14: 박사랑 | S14: 이소영 | U14: 고영숙; | V14: 윤분숙;
A15: 채린 | B15: =COUNTIF(I:AL,"채린") -> 0 | C15: 박창민 | D15: =COUNTIF(K:AN,"박창민;") -> 0 | U15: 최임이;
A16: 최임이 | B16: =COUNTIF(I:AL,"최임이") -> 0 | C16: 배이준 | D16: =COUNTIF(K:AN,"배이준;") -> 3 | H16: 4
A17: 김혜정 | B17: =COUNTIF(I:AL,"김혜정") -> 0 | C17: 임하령 | D17: =COUNTIF(K:AN,"임하령;") -> 0
A18: 박사랑 | B18: =COUNTIF(I:AL,"박사랑") -> 4 | C18: 이소영 | D18: =COUNTIF(K:AN,"이소영;") -> 2 | H18: 5 | U18: 신하린
A19: 신정인 | B19: =COUNTIF(I:AL,"신정인") -> 3 | C19: 이기찬 | D19: =COUNTIF(K:AN,"이기찬;") -> 3
H20: 6 | S20: 이소영; | T20: 정지원; | U20: 공하정;
S21: 임하린;
S22: 배이준;
S23: 이기찬;
H24: 7
H28: 2주차
A29: 민요개인 | C29: 민요단체 | D29: ; | E29: 장구단체 | F29: ] | I29: 12 | K29: 13 | M29: 14 | O29: 15 | Q29: 16 | S29: 17 | U29: 18
A30: 우리인력 | B30: =COUNTIF(I:AL,"우리인력") -> 5 | C30: 고영숙 | D30: =COUNTIF(I:AL,"고영숙;") -> 5 | E30: 고영숙 | F30: =COUNTIF(I:AL,"고영숙]") -> 0 | I30: 월 | K30: 화 | M30: 수 | O30: 목 | Q30: 금 | S30: 토 | U30: 일
A31: 김혜숙 | B31: =COUNTIF(I:AL,"김혜숙") -> 0 | C31: 공하정 | D31: =COUNTIF(I:AL,"공하정;") -> 1 | E31: 공하정 | F31: =COUNTIF(I:AL,"공하정]") -> 0 | H31: 10
A32: 배이준 | B32: =COUNTIF(I:AL,"배이준") -> 3 | C32: 김다정 | D32: =COUNTIF(I:AL,"김다정;") -> 0 | E32: 소영하린 | F32: =COUNTIF(I:AL,"소영하린]") -> 2
A33: 신하린 | B33: =COUNTIF(I:AL,"신하린") -> 2 | C33: 김용 | D33: =COUNTIF(I:AL,"김용;") -> 3 | H33: 11 | Q33: 이기찬
A34: 아름다움 | B34: =COUNTIF(I:AL,"아름다움") -> 0 | C34: 윤분숙 | D34: =COUNTIF(I:AL,"윤분숙;") -> 4
A35: 이기찬 | B35: =COUNTIF(I:AL,"이기찬") -> 3 | C35: 이말진 | D35: =COUNTIF(I:AL,"이말진;") -> 0 | H35: 12 | S35: 배이준
A36: 초연 | B36: =COUNTIF(I:AL,"초연") -> 0 | C36: 최임이 | D36: =COUNTIF(I:AL,"최임이;") -> 3
A37: 이소영 | B37: =COUNTIF(I:AL,"이소영") -> 5 | C37: 김혜정 | D37: =COUNTIF(I:AL,"김혜정;") -> 0 | H37: 1 | Q37: 이소영
A38: 임하령 | B38: =COUNTIF(I:AL,"임하령") -> 0
A39: 임하린 | B39: =COUNTIF(I:AL,"임하린") -> 4 | C39: 임하린 | D39: =COUNTIF(K:AN,"임하린;") -> 3 | H39: 2 | K39: 이소영 | O39: 임하린
A40: 정지원 | B40: =COUNTIF(I:AL,"정지원") -> 3 | C40: 정지원 | D40: =COUNTIF(K:AN,"정지원;") -> 3
A41: 최은실 | B41: =COUNTIF(I:AL,"최은실") -> 0 | C41: 초연 | D41: =COUNTIF(K:AN,"초연;") -> 0 | H41: 3 | M41: 김용; | N41: 윤분숙; | O41: 정지원
A42: 박창민 | B42: =COUNTIF(I:AL,"박창민") -> 0 | C42: 아름다움 | D42: =COUNTIF(K:AN,"아름다움;") -> 0 | M42: 고영숙; | N42: 최임이;
A43: 채린 | B43: =COUNTIF(I:AL,"채린") -> 0 | C43: 박창민 | D43: =COUNTIF(K:AN,"박창민;") -> 0 | H43: 4 | K43: 박사랑
...

Sheet 24년3월
A1: 개인 | C1: 단체 | D1: ; | E1: 심화 | F1: ] | H1: 1주차
A2: 구로 | B2: =COUNTIF(I:AL,"구로") -> 4 | C2: 고영숙 | D2: =COUNTIF(I:AL,"고영숙;") -> 4 | E2: 이소영 | F2: =COUNTIF(I:AL,"이소영]") -> 4 | I2: 1 | K2: 2 | M2: 3 | O2: 4 | Q2: 5 | S2: 6 | U2: 7 | W2: 8 | Y2: 9 | AA2: 10
A3: 우리인력 | B3: =COUNTIF(I:AL,"우리인력") -> 4 | C3: 김용 | D3: =COUNTIF(I:AL,"김용;") -> 4 | E3: 소영하린 | F3: =COUNTIF(I:AL,"소영하린]") -> 4 | I3: 금 | K3: 토 | M3: 일 | O3: 월 | Q3: 화 | S3: 수 | U3: 목 | W3: 금 | Y3: 토 | AA3: 일
A4: 박사랑 | B4: =COUNTIF(I:AL,"박사랑") -> 4 | C4: 윤분숙 | D4: =COUNTIF(I:AL,"윤분숙;") -> 4 | H4: 10
A5: 이소영 | B5: =COUNTIF(I:AL,"이소영") -> 4 | C5: 최임이 | D5: =COUNTIF(I:AL,"최임이;") -> 4
A6: 임하린 | B6: =COUNTIF(I:AL,"임하린") -> 4 | C6: 이말진 | D6: =COUNTIF(I:AL,"이말진;") -> 3 | H6: 11 | Q6: 박사랑
A7: 정지원 | B7: =COUNTIF(I:AL,"정지원") -> 4 | C7: 김인애 | D7: =COUNTIF(I:AL,"김인애;") -> 4
A8: 이기찬 | B8: =COUNTIF(I:AL,"이기찬") -> 3 | C8: 석경남 | D8: =COUNTIF(I:AL,"석경남;") -> 5 | H8: 12
A9: 배이준 | B9: =COUNTIF(I:AL,"배이준") -> 3 | C9: 윤미호 | D9: =COUNTIF(I:AL,"윤미호;") -> 4
A10: 신정인 | B10: =COUNTIF(I:AL,"신정인") -> 2 | C10: 김견희 | D10: =COUNTIF(I:AL,"김견희;") -> 4 | H10: 1 | O10: 구로
A11: 변이서 | B11: =COUNTIF(I:AL,"변이서") -> 4 | C11: 박상혜 | D11: =COUNTIF(I:AL,"박상혜;") -> 2
A12: 박창민 | B12: =COUNTIF(I:AL,"박창민") -> 4 | C12: 신하린 | D12: =COUNTIF(I:AL,"신하린;") -> 1 | H12: 2 | Q12: 이소영
A13: 정윤후 | B13: =COUNTIF(I:AL,"정윤후") -> 3 | C13: 김혜정 | D13: =COUNTIF(I:AL,"김혜정;") -> 1
A14: 이순희 | B14: =COUNTIF(M:AP,"이순희") -> 2 | H14: 3 | Q14: 소영하린] | S14: 고영숙; | T14: 최임이; | U14: 임하린 | W14: 박창민
S15: 윤분숙; | T15: 김용;
H16: 4 | U16: 정지원 | W16: 변이서 | Y16: 배이준
C18: 공하정 | D18: =COUNTIF(I:AL,"공하정;") -> 0 | H18: 5 | Q18: 이기찬 | Y18: 이소영]
C19: 임하린 | D19: =COUNTIF(K:AN,"임하린;") -> 4
C20: 정지원 | D20: =COUNTIF(K:AN,"정지원;") -> 4 | H20: 6 | Q20: 이소영; | R20: 정지원; | S20: 이말진;
C21: 배이준 | D21: =COUNTIF(K:AN,"배이준;") -> 3 | Q21: 임하린; | R21: 이기찬;
C22: 이소영 | D22: =COUNTIF(K:AN,"이소영;") -> 4 | Q22: 배이준;
C23: 이기찬 | D23: =COUNTIF(K:AN,"이기찬;") -> 3
A24: 최은실 | B24: =COUNTIF(I:AL,"최은실") -> 0 | C24: 박창민 | D24: =COUNTIF(K:AN,"박창민;") -> 0 | H24: 7
A25: 김혜숙 | B25: =COUNTIF(I:AL,"김혜숙") -> 0
A28: 개인 | C28: 단체 | D28: ; | E28: 심화 | F28: ] | H28: 2주차
A29: 구로 | B29: =COUNTIF(I:AL,"구로") -> 4 | C29: 고영숙 | D29: =COUNTIF(I:AL,"고영숙;") -> 4 | E29: 이소영 | F29: =COUNTIF(I:AL,"이소영]") -> 4 | I29: 11 | K29: 12 | M29: 13 | O29: 14 | Q29: 15 | S29: 16 | U29: 17
A30: 우리인력 | B30: =COUNTIF(I:AL,"우리인력") -> 4 | C30: 김용 | D30: =COUNTIF(I:AL,"김용;") -> 4 | E30: 소영하린 | F30: =COUNTIF(I:AL,"소영하린]") -> 4 | I30: 월 | K30: 화 | M30: 수 | O30: 목 | Q30: 금 | S30: 토 | U30: 일
A31: 박사랑 | B31: =COUNTIF(I:AL,"박사랑") -> 4 | C31: 윤분숙 | D31: =COUNTIF(I:AL,"윤분숙;") -> 4 | H31: 10 | I31: 우리인력 | O31: 우리인력 | Q31: 김인애; | R31: 석경남;
A32: 이소영 | B32: =COUNTIF(I:AL,"이소영") -> 4 | C32: 최임이 | D32: =COUNTIF(I:AL,"최임이;") -> 4
A33: 임하린 | B33: =COUNTIF(I:AL,"임하린") -> 4 | C33: 이말진 | D33: =COUNTIF(I:AL,"이말진;") -> 3 | H33: 11 | M33: 신정인
A34: 정지원 | B34: =COUNTIF(I:AL,"정지원") -> 4 | C34: 김인애 | D34: =COUNTIF(I:AL,"김인애;") -> 4
A35: 이기찬 | B35: =COUNTIF(I:AL,"이기찬") -> 3 | C35: 석경남 | D35: =COUNTIF(I:AL,"석경남;") -> 5 | H35: 12 | M35: 변이서
A36: 배이준 | B36: =COUNTIF(I:AL,"배이준") -> 3 | C36: 윤미호 | D36: =COUNTIF(I:AL,"윤미호;") -> 4
A37: 신정인 | B37: =COUNTIF(I:AL,"신정인") -> 2 | C37: 김견희 | D37: =COUNTIF(I:AL,"김견희;") -> 4 | H37: 1 | I37: 구로 | Q37: 배이준
A38: 변이서 | B38: =COUNTIF(I:AL,"변이서") -> 4 | C38: 박상혜 | D38: =COUNTIF(I:AL,"박상혜;") -> 2
A39: 박창민 | B39: =COUNTIF(I:AL,"박창민") -> 4 | C39: 신하린 | D39: =COUNTIF(I:AL,"신하린;") -> 1 | H39: 2 | K39: 이소영 | Q39: 박창민 | S39: 이소영]
A40: 정윤후 | B40: =COUNTIF(I:AL,"정윤후") -> 3 | C40: 김혜정 | D40: =COUNTIF(I:AL,"김혜정;") -> 1
A41: 이순희 | B41: =COUNTIF(M:AP,"이순희") -> 2 | H41: 3 | K41: 소영하린] | M41: 고영숙; | N41: 최임이; | O41: 임하린 | S41: 윤미호; | T41: 김견희;
M42: 윤분숙; | N42: 김용;
H43: 4 | I43: 박사랑 | K43: 이기찬 | M43: 김인애; | N43: 석경남; | O43: 정지원 | S43: 정윤후
...

Sheet 24년4월
A1: 개인 | C1: 단체 | D1: ; | E1: 심화 | F1: ] | H1: 1주차
A2: 구로 | B2: =COUNTIF(I:AL,"구로") -> 3 | C2: 고영숙 | D2: =COUNTIF(I:AL,"고영숙;") -> 4 | E2: 이소영 | F2: =COUNTIF(I:AL,"이소영]") -> 2 | I2: 1 | K2: 2 | M2: 3 | O2: 4 | Q2: 5 | S2: 6 | U2: 7
A3: 우리인력 | B3: =COUNTIF(I:AL,"우리인력") -> 5 | C3: 김용 | D3: =COUNTIF(I:AL,"김용;") -> 4 | E3: 소영하린 | F3: =COUNTIF(I:AL,"소영하린]") -> 3 | I3: 월 | K3: 화 | M3: 수 | O3: 목 | Q3: 금 | S3: 토 | U3: 일
A4: 박사랑 | B4: =COUNTIF(I:AL,"박사랑") -> 6 | C4: 윤분숙 | D4: =COUNTIF(I:AL,"윤분숙;") -> 1 | E4: 이말진 | F4: =COUNTIF(I:AL,"이말진]") -> 1 | H4: 10 | I4: 우리인력 | O4: 우리인력
A5: 이소영 | B5: =COUNTIF(I:AL,"이소영") -> 5 | C5: 최임이 | D5: =COUNTIF(I:AL,"최임이;") -> 4 | E5: 변이서 | F5: =COUNTIF(I:AL,"변이서]") -> 0
A6: 임하린 | B6: =COUNTIF(I:AL,"임하린") -> 4 | C6: 이말진 | D6: =COUNTIF(I:AL,"이말진;") -> 4 | H6: 11
A7: 정지원 | B7: =COUNTIF(I:AL,"정지원") -> 4 | C7: 김인애 | D7: =COUNTIF(I:AL,"김인애;") -> 3
A8: 이기찬 | B8: =COUNTIF(I:AL,"이기찬") -> 5 | C8: 석경남 | D8: =COUNTIF(I:AL,"석경남;") -> 4 | H8: 12
A9: 배이준 | B9: =COUNTIF(I:AL,"배이준") -> 2 | C9: 박상혜 | D9: =COUNTIF(I:AL,"박상혜;") -> 4
A10: 신정인 | B10: =COUNTIF(I:AL,"신정인") -> 2 | C10: 신하린 | D10: =COUNTIF(I:AL,"신하린;") -> 1 | H10: 1 | I10: 구로 | O10: 신정인
A11: 변이서 | B11: =COUNTIF(I:AL,"변이서") -> 9 | C11: 김혜정 | D11: =COUNTIF(I:AL,"김혜정;") -> 1
A12: 박창민 | B12: =COUNTIF(I:AL,"박창민") -> 7 | C12: 장유진 | D12: =COUNTIF(I:AL,"장유진;") -> 2 | H12: 2
A13: 정윤후 | B13: =COUNTIF(I:AL,"정윤후") -> 3 | C13: 임인숙 | D13: =COUNTIF(I:AL,"임인숙;") -> 2
A14: 이순희 | B14: =COUNTIF(M:AP,"이순희") -> 4 | H14: 3 | K14: 이소영 | M14: 고영숙; | N14: 최임이; | O14: 윤미호 | P14: 김견희 | Q14: 박창민
A15: 박상혜 | B15: =COUNTIF(I:AP,"박상혜") -> 3 | M15: 윤분숙; | N15: 김용;
A16: 윤미호 | B16: =COUNTIF(G:AJ,"윤미호") -> 3 | H16: 4 | I16: 박사랑 | K16: 소영하린] | M16: 김인애; | N16: 석경남; | O16: 임하린 | Q16: 변이서
A17: 김견희 | B17: =COUNTIF(G:AJ,"김견희") -> 3
A18: 김하윤 | B18: =COUNTIF(G:AJ,"김하윤") -> 2 | C18: 공하정 | D18: =COUNTIF(I:AL,"공하정;") -> 0 | H18: 5 | K18: 이기찬 | M18: 이말진; | N18: 박상혜; | O18: 정지원 | Q18: 윤미호; | R18: 김견희;
A19: 이말진 | B19: =COUNTIF(G:AJ,"이말진") -> 1 | C19: 임하린 | D19: =COUNTIF(K:AN,"임하린;") -> 5
A20: 김지온 | B20: =COUNTIF(G:AJ,"김지온") -> 1 | C20: 정지원 | D20: =COUNTIF(K:AN,"정지원;") -> 5 | H20: 6 | K20: 이소영; | L20: 정지원; | Q20: 이순희
A21: 김미지 | B21: =COUNTIF(G:AJ,"김미지") -> 2 | C21: 배이준 | D21: =COUNTIF(K:AN,"배이준;") -> 5 | K21: 임하린; | L21: 이기찬;
C22: 이소영 | D22: =COUNTIF(K:AN,"이소영;") -> 5 | K22: 배이준;
C23: 이기찬 | D23: =COUNTIF(K:AN,"이기찬;") -> 5
A24: 최은실 | B24: =COUNTIF(I:AL,"최은실") -> 0 | C24: 박창민 | D24: =COUNTIF(K:AN,"박창민;") -> 1 | H24: 7
A25: 김혜숙 | B25: =COUNTIF(I:AL,"김혜숙") -> 0
H28: 2주차
I29: 8 | K29: 9 | M29: 10 | O29: 11 | Q29: 12 | S29: 13 | U29: 14
I30: 월 | K30: 화 | M30: 수 | O30: 목 | Q30: 금 | S30: 토 | U30: 일
H31: 10 | I31: 우리인력 | O31: 우리인력
H33: 11
H35: 12
H37: 1 | I37: 구로 | S37: 박창민
H39: 2
H41: 3 | K41: 이소영 | M41: 고영숙; | N41: 최임이; | O41: 임하린
M42: 김용;
H43: 4 | I43: 박사랑 | K43: 소영하린] | M43: 김인애; | N43: 석경남; | O43: 정지원 | Q43: 변이서 | S43: 정윤후
H45: 5 | K45: 이기찬 | M45: 이말진; | N45: 박상혜; | S45: 배이준
H47: 6 | I47: 박상혜 | K47: 이소영; | L47: 정지원; | Q47: 이순희
K48: 임하린; | L48: 이기찬;
K49: 배이준;
...

Sheet 24년5월
A1: 개인 | C1: 단체 | D1: ; | E1: 심화 | F1: ] | H1: 1주차
A2: 구로 | B2: =COUNTIF(I:AL,"구로") -> 3 | C2: 고영숙 | D2: =COUNTIF(I:AL,"고영숙;") -> 4 | E2: 이소영 | F2: =COUNTIF(I:AL,"이소영]") -> 1 | I2: 1 | K2: 2 | M2: 3 | O2: 4 | Q2: 5
A3: 우리인력 | B3: =COUNTIF(I:AL,"우리인력") -> 1 | C3: 김용 | D3: =COUNTIF(I:AL,"김용;") -> 3 | E3: 이말진 | F3: =COUNTIF(I:AL,"이말진]") -> 0 | I3: 수 | K3: 목 | M3: 금 | O3: 토 | Q3: 일
A4: 박사랑 | B4: =COUNTIF(I:AL,"박사랑") -> 3 | C4: 윤분숙 | D4: =COUNTIF(I:AL,"윤분숙;") -> 4 | E4: 변이서 | F4: =COUNTIF(I:AL,"변이서]") -> 0 | H4: 10 | K4: 우리인력 | O4: 어린이날 행사
A5: 이소영 | B5: =COUNTIF(I:AL,"이소영") -> 7 | C5: 최임이 | D5: =COUNTIF(I:AL,"최임이;") -> 0
A6: 임하린 | B6: =COUNTIF(I:AL,"임하린") -> 2 | C6: 이말진 | D6: =COUNTIF(I:AL,"이말진;") -> 2 | H6: 11
A7: 정지원 | B7: =COUNTIF(I:AL,"정지원") -> 3 | C7: 김인애 | D7: =COUNTIF(I:AL,"김인애;") -> 1
A8: 이기찬 | B8: =COUNTIF(I:AL,"이기찬") -> 3 | C8: 석경남 | D8: =COUNTIF(I:AL,"석경남;") -> 3 | H8: 12
A9: 배이준 | B9: =COUNTIF(I:AL,"배이준") -> 2 | C9: 박상혜 | D9: =COUNTIF(I:AL,"박상혜;") -> 2
A10: 신정인 | B10: =COUNTIF(I:AL,"신정인") -> 3 | C10: 신하린 | D10: =COUNTIF(I:AL,"신하린;") -> 1 | H10: 1 | I10: 김미지
A11: 변이서 | B11: =COUNTIF(I:AL,"변이서") -> 2 | C11: 김혜정 | D11: =COUNTIF(I:AL,"김혜정;") -> 4
A12: 박창민 | B12: =COUNTIF(I:AL,"박창민") -> 3 | C12: 장유진 | D12: =COUNTIF(I:AL,"장유진;") -> 0 | H12: 2 | I12: 김미지
A13: 정윤후 | B13: =COUNTIF(I:AL,"정윤후") -> 1 | C13: 임인숙 | D13: =COUNTIF(I:AL,"임인숙;") -> 0
A14: 이순희 | B14: =COUNTIF(I:AP,"이순희") -> 1 | H14: 3 | I14: 신정인 | J14: 고영숙; | K14: 임하린
A15: 박상혜 | B15: =COUNTIF(I:AP,"박상혜") -> 4 | I15: 김혜정; | J15: 김용;
A16: 윤미호 | B16: =COUNTIF(G:AJ,"윤미호") -> 4 | H16: 4 | I16: 석경남; | J16: 박상혜; | K16: 윤미호 | L16: 김견희
A17: 김견희 | B17: =COUNTIF(G:AJ,"김견희") -> 3 | I17: 이말진; | J17: 윤분숙;
A18: 김하윤 | B18: =COUNTIF(G:AJ,"김하윤") -> 1 | C18: 변이서 | D18: =COUNTIF(H$2:AN$1048576,"변이서;") -> 2 | H18: 5
A19: 이말진 | B19: =COUNTIF(G:AJ,"이말진") -> 2 | C19: 정지원 | D19: =COUNTIF(H$2:AN$1048576,"정지원;") -> 4
A20: 김지온 | B20: =COUNTIF(G:AJ,"김지온") -> 1 | C20: 박사랑 | D20: =COUNTIF(H$2:AN$1048576,"박사랑;") -> 3 | H20: 6 | I20: 변이서;; | J20: 이소영;;
A21: 김미지 | B21: =COUNTIF(G:AJ,"김미지") -> 4 | C21: 김하윤 | D21: =COUNTIF(H$2:AN$1048576,"김하윤;") -> 3 | I21: 임하린;; | J21: 박창민;;
C22: 김지온 | D22: =COUNTIF(H$2:AN$1048576,"김지온;") -> 4 | I22: 김하윤;; | J22: 박사랑;;
C23: 박창민 | D23: =COUNTIF(H:AN,"박창민;") -> 2
C24: 이기찬 | D24: =COUNTIF(H:AN,"이기찬;") -> 2 | H24: 7
H28: 2주차
I29: 6 | K29: 7 | M29: 8 | O29: 9 | Q29: 10 | S29: 11 | U29: 12
I30: 월 | K30: 화 | M30: 수 | O30: 목 | Q30: 금 | S30: 토 | U30: 일
H31: 10
H33: 11 | S33: 이말진
H35: 12 | S35: 이말진
H37: 1 | M37: 김미지 | S37: 김지온
H39: 2 | M39: 김미지 | S39: 김하윤
H41: 3 | M41: 석경남; | N41: 김인애; | Q41: 박창민 | S41: 정윤후
M42: 김용; | N42: 윤분숙;
H43: 4 | K43: 김지온; | L43: 정지원; | M43: 김혜정; | N43: 고영숙; | O43: 박사랑 | Q43: 정지원 | S43: 배이준
H45: 5 | I45: 신정인 | O45: 윤미호 | P45: 김견희 | S45: 이소영]
H47: 6 | I47: 박상혜
H51: 7 | O51: 해금
H56: 3주차
I57: 13 | K57: 14 | M57: 15 | O57: 16 | Q57: 17 | S57: 18 | U57: 19
...

Sheet 24년6월
A1: 개인 | C1: 단체 | D1: ; | E1: 심화 | F1: ] | H1: 1주차
A2: 구로 | B2: =COUNTIF(I:AL,"구로") -> 1 | C2: 고영숙 | D2: =COUNTIF(I:AL,"고영숙;") -> 3 | E2: 이소영 | F2: =COUNTIF(I:AL,"이소영]") -> 3 | I2: 1 | K2: 2 | M2: 3 | O2: 4 | Q2: 5 | S2: 6 | U2: 7 | W2: 8 | Y2: 9
A3: 우리인력 | B3: =COUNTIF(I:AL,"우리인력") -> 0 | C3: 김용 | D3: =COUNTIF(I:AL,"김용;") -> 3 | E3: 이말진 | F3: =COUNTIF(I:AL,"이말진]") -> 0 | I3: 토 | K3: 일 | M3: 월 | O3: 화 | Q3: 수 | S3: 목 | U3: 금 | W3: 토 | Y3: 일
A4: 박사랑 | B4: =COUNTIF(I:AL,"박사랑") -> 3 | C4: 윤분숙 | D4: =COUNTIF(I:AL,"윤분숙;") -> 3 | E4: 변이서 | F4: =COUNTIF(I:AL,"변이서]") -> 0 | H4: 10
A5: 이소영 | B5: =COUNTIF(I:AL,"이소영") -> 6 | C5: 최임이 | D5: =COUNTIF(I:AL,"최임이;") -> 2
A6: 임하린 | B6: =COUNTIF(I:AL,"임하린") -> 4 | C6: 이말진 | D6: =COUNTIF(I:AL,"이말진;") -> 0 | H6: 11
A7: 정지원 | B7: =COUNTIF(I:AL,"정지원") -> 3 | C7: 김인애 | D7: =COUNTIF(I:AL,"김인애;") -> 0
A8: 이기찬 | B8: =COUNTIF(I:AL,"이기찬") -> 4 | C8: 석경남 | D8: =COUNTIF(I:AL,"석경남;") -> 1 | H8: 12
A9: 배이준 | B9: =COUNTIF(I:AL,"배이준") -> 4 | C9: 박상혜 | D9: =COUNTIF(I:AL,"박상혜;") -> 0
A10: 신정인 | B10: =COUNTIF(I:AL,"신정인") -> 0 | C10: 신하린 | D10: =COUNTIF(I:AL,"신하린;") -> 3 | H10: 1 | M10: 구로
A11: 변이서 | B11: =COUNTIF(I:AL,"변이서") -> 3 | C11: 김혜정 | D11: =COUNTIF(I:AL,"김혜정;") -> 0
A12: 박창민 | B12: =COUNTIF(I:AL,"박창민") -> 3 | H12: 2 | I12: 김하윤
A13: 정윤후 | B13: =COUNTIF(I:AL,"정윤후") -> 0
A14: 이순희 | B14: =COUNTIF(I:AP,"이순희") -> 2 | H14: 3 | O14: 이소영 | Q14: 윤분숙; | R14: 석경남; | S14: 임하린 | U14: 김서현
A15: 박상혜 | B15: =COUNTIF(I:AP,"박상혜") -> 1 | Q15: 김용; | R15: 고영숙;
A16: 윤미호 | B16: =COUNTIF(G:AJ,"윤미호") -> 5 | C16: 변이서 | D16: =COUNTIF(H$2:AN$1048576,"변이서;") -> 3 | H16: 4 | M16: 박사랑 | O16: 이소영] | Q16: 하성순 | U16: 박창민
A17: 김견희 | B17: =COUNTIF(G:AJ,"김견희") -> 0 | C17: 정지원 | D17: =COUNTIF(H$2:AN$1048576,"정지원;") -> 4
A18: 김하윤 | B18: =COUNTIF(G:AJ,"김하윤") -> 3 | C18: 박사랑 | D18: =COUNTIF(H$2:AN$1048576,"박사랑;") -> 4 | H18: 5 | I18: 배이준 | M18: 변이서 | O18: 김지온 | P18: 김하윤 | Q18: 윤미호 | U18: 정지원 | W18: 배이준
A19: 이말진 | B19: =COUNTIF(G:AJ,"이말진") -> 0 | C19: 김하윤 | D19: =COUNTIF(H$2:AN$1048576,"김하윤;") -> 4 | O19: 이기찬
A20: 김지온 | B20: =COUNTIF(G:AJ,"김지온") -> 2 | C20: 김지온 | D20: =COUNTIF(H$2:AN$1048576,"김지온;") -> 4 | H20: 6 | M20: 박상혜 | O20: 김지온; | P20: 김하윤; | Q20: 신하린;
A21: 김서현 | B21: =COUNTIF(G:AJ,"김서현") -> 3 | C21: 박창민 | D21: =COUNTIF(H:AN,"박창민;") -> 4 | O21: 박사랑; | P21: 박창민;
A22: 하성순 | B22: =COUNTIF(G:AJ,"하성순") -> 3 | C22: 이기찬 | D22: =COUNTIF(H:AN,"이기찬;") -> 3 | O22: 정지원;
C23: 김서현 | D23: =COUNTIF(H:AN,"김서현;") -> 2
H24: 7
H28: 2주차
I29: 10 | K29: 11 | M29: 12 | O29: 13 | Q29: 14 | S29: 15 | U29: 16
I30: 월 | K30: 화 | M30: 수 | O30: 목 | Q30: 금 | S30: 토 | U30: 일
H31: 10
H33: 11
H35: 12
H37: 1
H39: 2 | O39: 하성순
H41: 3 | K41: 이소영 | M41: 윤분숙; | N41: 최임이; | O41: 임하린 | Q41: 박창민
M42: 김용; | N42: 고영숙;
H43: 4 | I43: 박사랑 | K43: 이소영] | Q43: 이소영
H45: 5 | K45: 이기찬 | M45: 윤미호 | N45: 신하린; | Q45: 정지원 | S45: 배이준
H47: 6 | K47: 김지온; | L47: 김하윤; | M47: 윤미호 | Q47: 이순희
K48: 박사랑; | L48: 박창민;
K49: 정지원; | L49: 김서현;
K50: 변이서; | L50: 이기찬;
...

Sheet 24년7월
A1: 개인 | C1: 단체 | D1: ; | E1: 심화 | F1: ] | H1: 1주차
A2: 구로 | B2: =COUNTIF(I:AL,"구로") -> 0 | C2: 고영숙 | D2: =COUNTIF(I:AL,"고영숙;") -> 1 | E2: 이소영 | F2: =COUNTIF(I:AL,"이소영]") -> 0 | I2: 1 | K2: 2 | M2: 3 | O2: 4 | Q2: 5 | S2: 6 | U2: 7
A3: 박사랑 | B3: =COUNTIF(I:AL,"박사랑") -> 0 | C3: 김용 | D3: =COUNTIF(I:AL,"김용;") -> 1 | E3: 이말진 | F3: =COUNTIF(I:AL,"이말진]") -> 0 | I3: 월 | K3: 화 | M3: 수 | O3: 목 | Q3: 금 | S3: 토 | U3: 일
A4: 이소영 | B4: =COUNTIF(I:AL,"이소영") -> 1 | C4: 윤분숙 | D4: =COUNTIF(I:AL,"윤분숙;") -> 1 | H4: 10
A5: 임하린 | B5: =COUNTIF(I:AL,"임하린") -> 1 | C5: 최임이 | D5: =COUNTIF(I:AL,"최임이;") -> 1
A6: 정지원 | B6: =COUNTIF(I:AL,"정지원") -> 0 | C6: 이말진 | D6: =COUNTIF(I:AL,"이말진;") -> 1 | H6: 11
A7: 이기찬 | B7: =COUNTIF(I:AL,"이기찬") -> 1 | C7: 김인애 | D7: =COUNTIF(I:AL,"김인애;") -> 0
A8: 배이준 | B8: =COUNTIF(I:AL,"배이준") -> 0 | C8: 석경남 | D8: =COUNTIF(I:AL,"석경남;") -> 1 | H8: 12
A9: 신정인 | B9: =COUNTIF(I:AL,"신정인") -> 1 | C9: 박상혜 | D9: =COUNTIF(I:AL,"박상혜;") -> 0
A10: 변이서 | B10: =COUNTIF(I:AL,"변이서") -> 0 | C10: 신하린 | D10: =COUNTIF(I:AL,"신하린;") -> 0 | H10: 1
A11: 박창민 | B11: =COUNTIF(I:AL,"박창민") -> 0 | C11: 김혜정 | D11: =COUNTIF(I:AL,"김혜정;") -> 0
A12: 정윤후 | B12: =COUNTIF(I:AL,"정윤후") -> 0 | H12: 2
A13: 이순희 | B13: =COUNTIF(I:AP,"이순희") -> 0
A14: 박상혜 | B14: =COUNTIF(I:AP,"박상혜") -> 0 | C14: 변이서 | D14: =COUNTIF(H$2:AN$1048576,"변이서;") -> 1 | H14: 3 | K14: 이소영 | M14: 윤분숙; | N14: 최임이; | O14: 신정인
A15: 윤미호 | B15: =COUNTIF(G:AJ,"윤미호") -> 2 | C15: 정지원 | D15: =COUNTIF(H$2:AN$1048576,"정지원;") -> 0 | M15: 김용; | N15: 고영숙;
A16: 김견희 | B16: =COUNTIF(G:AJ,"김견희") -> 0 | C16: 박사랑 | D16: =COUNTIF(H$2:AN$1048576,"박사랑;") -> 0 | H16: 4 | M16: 석경남; | O16: 임하린
A17: 이말진 | B17: =COUNTIF(G:AJ,"이말진") -> 0 | C17: 박창민 | D17: =COUNTIF(H:AN,"박창민;") -> 0
A18: 김서현 | B18: =COUNTIF(G:AJ,"김서현") -> 0 | C18: 이기찬 | D18: =COUNTIF(H:AN,"이기찬;") -> 1 | H18: 5 | K18: 이기찬 | M18: 윤미호 | N18: 이말진; | O18: 윤미호
A19: 정승은 | B19: =COUNTIF(G:AJ,"정승은") -> 0 | C19: 김서현 | D19: =COUNTIF(H:AN,"김서현;") -> 0
A20: 정서은 | B20: =COUNTIF(G:AJ,"정서은") -> 0 | C20: 음채원 | D20: =COUNTIF(H:AN,"음채원;") -> 1 | H20: 6 | K20: 이기찬; | L20: 음채원;
A21: 음채원 | B21: =COUNTIF(G:AJ,"음채원") -> 0 | C21: 정승은 | D21: =COUNTIF(I:AL,"정승은;") -> 0 | K21: 변이서;
C22: 정서은 | D22: =COUNTIF(I:AL,"정서은;") -> 0
H24: 7
H28: 2주차
I29: 8 | K29: 9 | M29: 10 | O29: 11 | Q29: 12 | S29: 13 | U29: 14
I30: 월 | K30: 화 | M30: 수 | O30: 목 | Q30: 금 | S30: 토 | U30: 일
H31: 10
H33: 11
H35: 12
H37: 1
H39: 2
H41: 3
H43: 4
H45: 5
H47: 6
H51: 7
H56: 3주차
I57: 15 | K57: 16 | M57: 17 | O57: 18 | Q57: 19 | S57: 20 | U57: 21
I58: 월 | K58: 화 | M58: 수 | O58: 목 | Q58: 금 | S58: 토 | U58: 일
H59: 10
...

Sheet 악기24년
A1: 총 수입 | B1: =SUM(G3,I3,K3,M3,O3,Q3,S3,U3,W3,Y3,AA3,AC3) -> 3
A2: 번호 | B2: 이름 | C2: 전화번호 | D2: 대여기간 | E2: 대여비 | F2: 1월 | G2: 입금 | H2: 2월 | I2: 입금 | J2: 3월 | K2: 입금 | L2: 4월 | M2: 입금 | N2: 5월 | O2: 입금 | P2: 6월 | Q2: 입금 | R2: 7월 | S2: 입금 | T2: 8월 | U2: 입금 | V2: 9월 | W2: 입금 | X2: 10월 | Y2: 입금 | Z2: 11월 | AA2: 입금 | AB2: 12월 | AC2: 입금
A3: 1 | B3: 홍길동 | C3: 010-123-4567 | D3: 1개월 | E3: =SUM(E5:E45) -> 3 | G3: =SUM(G5:G25) -> 0 | I3: =SUM(I5:I25) -> 0 | K3: =SUM(K5:K25) -> 0 | M3: =SUM(M5:M25) -> 0 | O3: =SUM(O5:O25) -> 3 | Q3: =SUM(Q5:Q25) -> 0 | S3: =SUM(S5:S25) -> 0 | U3: =SUM(U5:U25) -> 0 | W3: =SUM(W5:W25) -> 0 | Y3: =SUM(Y5:Y25) -> 0 | AA3: =SUM(AA5:AA25) -> 0 | AC3: =SUM(AC4:AC25) -> 0
A4: 가야금
A5: 1
A6: 2
A7: 3
A8: 4
A9: 총인원 | B9: 0명
A11: 해금
A12: 1 | B12: 김다영 | C12: 10만원보증금 | D12: 1개월 | E12: 3 | N12: 2 | O12: 3
A13: 2
A14: 3
A15: 4
A16: 5
A17: 총인원 | B17: 0명
A19: 기타
A20: 1
A21: 2
A22: 3
A23: 4
A24: 총인원 | B24: 0명

Sheet 123
A1: 번호 | B1: 이름 | C1: 전화번호 | D1: 과목 | E1: 대여기간 | F1: 대여비 | G1: 1달 | H1: 2달 | I1: 3달 | J1: 4달 | K1: 5달 | L1: 6달 | M1: 7달 | N1: 8달 | O1: 9달 | P1: 10달 | Q1: 11달 | R1: 12달
A3: 1 | B3: 조은서 | C3: 010-4106-9365 | D3: 가야금 | E3: 2개월 | F3: 16 | G3: 45121 | H3: 45152
A4: 2 | B4: 김민채 | C4: 010-72078055 | D4: 해금 | E4: 1개월 | F4: 13 | G4: 45135 | H4: 45166
A5: 3
A6: 4
A7: 5
A8: 6
A9: 7
A10: 8
A11: 9
A12: 10
A13: 11
A14: 12
A15: 13
A16: 14
... A22: 20

Sheet 구로
B1: 구로
A3: 24 총 합 | B3: =SUM(D10:O10) -> 140.7 | C3: 책 | D3: 4 | E3: 8 | F3: 16 | G3: 7 | H3: 3 | I3: 2 | K3: 2 | P3: =SUM(D3:O3) -> 42
C4: 24년 | D4: 1 | E4: 2 | F4: 3 | G4: 4 | H4: 5 | I4: 6 | J4: 7 | K4: 8 | L4: 9 | M4: 10 | N4: 11 | O4: 12
C5: 1 | E5: 0.8 | F5: 17.6 | G5: 6 | H5: 15.4 | I5: 13.6 | J5: 11.6 | K5: 7.7 | L5: 11.6 | M5: 11.6
C6: 2 | F6: 6 | G6: 17 | K6: 2
C7: 3 | E7: 3.2 | F7: 4 | H7: 1
C8: 4 | E8: 2.4 | F8: 4 | H8: 2
C9: 5 | D9: 3.2
D10: =SUM(D5:D9) -> 3.2 | E10: =SUM(E5:E9) -> 6.4 | F10: =SUM(F5:F9) -> 31.6 | G10: =SUM(G5:G9) -> 23 | H10: =SUM(H5:H9) -> 18.4 | I10: =SUM(I5:I9) -> 13.6 | J10: =SUM(J5:J9) -> 11.6 | K10: =SUM(K5:K9) -> 9.7 | ... O10: =SUM(O5:O9) -> 0
A12: 25 총 합 | B12: =SUM(D19:O19) -> 0 | C12: 책 | P12: =SUM(D12:O12) -> 0
C13: 25년 | D13: 1 | E13: 2 | F13: 3 | G13: 4 | H13: 5 | I13: 6 | J13: 7 | K13: 8 | L13: 9 | M13: 10 | N13: 11 | O13: 12
C14: 1
C15: 2
C16: 3
C17: 4
C18: 5
D19: =SUM(D14:D18) -> 0 | E19: =SUM(E14:E18) -> 0 | F19: =SUM(F14:F18) -> 0 | G19: =SUM(G14:G18) -> 0 | H19: =SUM(H14:H18) -> 0 | I19: =SUM(I14:I18) -> 0 | J19: =SUM(J14:J18) -> 0 | K19: =SUM(K14:K18) -> 0 | ... O19: =SUM(O14:O18) -> 0
A21: 26 총 합 | B21: =SUM(D28:O28) -> 0 | C21: 책 | P21: =SUM(D21:O21) -> 0
C22: 25년 | D22: 1 | E22: 2 | F22: 3 | G22: 4 | H22: 5 | I22: 6 | J22: 7 | K22: 8 | L22: 9 | M22: 10 | N22: 11 | O22: 12
C23: 1
C24: 2
C25: 3
C26: 4
C27: 5
D28: =SUM(D23:D27) -> 0 | E28: =SUM(E23:E27) -> 0 | F28: =SUM(F23:F27) -> 0 | G28: =SUM(G23:G27) -> 0 | H28: =SUM(H23:H27) -> 0 | I28: =SUM(I23:I27) -> 0 | J28: =SUM(J23:J27) -> 0 | K28: =SUM(K23:K27) -> 0 | ... O28: =SUM(O23:O27) -> 0

Sheet 외부23년
A2: 번호 | B2: 이름 | C2: 전화번호 | D2: 과목 | E2: 개인/단체 | F2: 수업 시간 | H2: 회비 | J2: 1달 | K2: 입금 | L2: 2달 | M2: 입금 | N2: 3달 | O2: 입금 | P2: 4달 | Q2: 입금 | R2: 5달 | S2: 입금 | T2: 6달 | U2: 입금 | V2: 7달 | W2: 입금 | X2: 8달 | Y2: 입금 | Z2: 9달 | AA2: 입금 | AB2: 10달 | AC2: 입금 | AD2: 11달 | AE2: 입금 | AF2: 12달 | AG2: 입금
A4: 1 | B4: 5동대표 | C4: 010-4187-0829 | D4: 가야금 | E4: 단체 | F4: 금요일 4시30분 | G4: 3개월 | H4: 24 | J4: 45121 | L4: 45149 | N4: 45177 | P4: 45212 | R4: 45240 | T4: 45268 | V4: 44938
A5: 2 | B5: 조은서 | C5: 010-4106-9365 | D5: 가야금 | E5: 단체 | F5: 금요일 4시30분 | G5: 3개월 | H5: 24 | J5: 45107 | L5: 45135 | N5: 45163 | P5: 45191 | R5: 45226 | T5: 45254 | V5: 45282
A6: 3 | B6: 박헤진 | C6: 010-4109-7610 | D6: 가야금 | E6: 단체 | F6: 금요일 4시30분 | G6: 1개월 | H6: 10 | J6: 45114 | K6: 7 | L6: 45142 | N6: 45170 | P6: 45198
A7: 4 | B7: 이선영 | C7: 010-3466-3527 | D7: 가야금 | E7: 단체 | F7: 금요일 4시30분 | G7: 3개월 | H7: 24 | J7: 45128 | L7: 45156 | N7: 45164
A8: 5
A9: 6
A10: 7
A11: 8
A12: 9 | B12: 차여명 | C12: 010-2229-4973 | D12: 정가 | E12: 단체 | F12: 금요일 4시30분 | G12: 3개월 | H12: 24 | J12: 45114 | L12: 45142 | N12: 45170 | P12: 45198
A13: 10
A14: 11
A15: 12
A16: 13
A17: 14 | B17: 김민채 | C17: 010-7207-8055 | D17: 해금 | E17: 단체 | F17: 화요일 10시 | G17: 3개월 | H17: 24 | J17: 45111 | L17: 45139 | N17: 45167 | P17: 45195
A18: 15 | B18: 남선숙 | C18: 010-3399-8638 | D18: 해금 | E18: 단체 | F18: 화요일10시 | G18: 3개월 | H18: 24 | J18: 45118 | L18: 45146 | N18: 45174 | P18: 45202
A19: 16
A20: 17
A21: 18
A22: 19
A23: 20
A24: 21
A25: 22
A26: 23
A27: 24
A28: 25
A29: 26
A30: 27
... A60: 57

Sheet 악기25년
A1: 총 수입 | B1: =SUM(G3,I3,K3,M3,O3,Q3,S3,U3,W3,Y3,AA3,AC3) -> 0
A2: 번호 | B2: 이름 | C2: 전화번호 | D2: 대여기간 | E2: 대여비 | F2: 1월 | G2: 입금 | H2: 2월 | I2: 입금 | J2: 3월 | K2: 입금 | L2: 4월 | M2: 입금 | N2: 5월 | O2: 입금 | P2: 6월 | Q2: 입금 | R2: 7월 | S2: 입금 | T2: 8월 | U2: 입금 | V2: 9월 | W2: 입금 | X2: 10월 | Y2: 입금 | Z2: 11월 | AA2: 입금 | AB2: 12월 | AC2: 입금
A3: 1 | B3: 홍길동 | C3: 010-123-4567 | D3: 1개월 | E3: =SUM(E5:E45) -> 0 | G3: =SUM(G5:G25) -> 0 | I3: =SUM(I5:I25) -> 0 | K3: =SUM(K5:K25) -> 0 | M3: =SUM(M5:M25) -> 0 | O3: =SUM(O5:O25) -> 0 | Q3: =SUM(Q5:Q25) -> 0 | S3: =SUM(S5:S25) -> 0 | U3: =SUM(U5:U25) -> 0 | W3: =SUM(W5:W25) -> 0 | Y3: =SUM(Y5:Y25) -> 0 | AA3: =SUM(AA5:AA25) -> 0 | AC3: =SUM(AC4:AC25) -> 0
A4: 가야금
A5: 1
A6: 2
A7: 3
A8: 4
A9: 총인원 | B9: 0명
A11: 해금
A12: 1
A13: 2
A14: 3
A15: 4
A16: 5
A17: 총인원 | B17: 0명
A19: 기타
A20: 1
A21: 2
A22: 3
A23: 4
A24: 총인원 | B24: 0명

Sheet 23년구
A1: 번호 | B1: 이름 | C1: 전화번호 | D1: 과목 | E1: 개인/단체 | F1: 수업 시간 | H1: 회비 | I1: 책 | J1: 1달 | K1: 입금 | L1: 2달 | M1: 입금 | N1: 3달 | O1: 입금 | P1: 4달 | Q1: 입금 | R1: 5달 | S1: 입금 | T1: 6달 | U1: 입금 | V1: 7달 | W1: 입금 | X1: 8달 | Y1: 입금 | Z1: 9달 | AA1: 입금 | AB1: 10달 | AC1: 입금 | AD1: 11달 | AE1: 입금 | AF1: 12달 | AG1: 입금
A2: 1 | B2: 이소영 | C2: 010-3492-7247 | D2: 민요 | E2: 개인 | F2: 화요일 / 3시 | G2: 1개월 | H2: 15 | I2: 1만 | J2: 45095 | L2: 45123 | M2: 45132 | N2: 45151 | O2: 45160 | P2: 45179 | R2: 45207 | T2: 45235 | V2: 45263 | X2: 45291 | Z2: 45319 | AB2: 45347 | AD2: 45375 | AF2: 45403
A3: 2 | B3: 김다정 | C3: 010-8234-4080 | D3: 민요 | E3: 단체 | F3: 금요일/2시 | G3: 3개월 | H3: 24 | J3: 45095 | L3: 45123 | N3: 45151 | P3: 45179 | R3: 45207 | T3: 45235 | V3: 45263 | X3: 45291 | Z3: 45319 | AB3: 45347 | AD3: 45375 | AF3: 45403
A4: 3 | B4: 고영숙 | C4: 010-2293-6349 | D4: 민요 | E4: 단체 | F4: 수요일 5시 | G4: 1개월 | H4: 10 | J4: 45094 | L4: 45122 | N4: 45150 | O4: 45161 | P4: 45178 | R4: 45206 | T4: 45234 | V4: 45262 | X4: 45290 | Z4: 45318 | AB4: 45346 | AD4: 45374 | AF4: 45402
A5: 4 | B5: 공춘희 | C5: 010-9288-9750 | D5: 민요 | E5: 단체 | F5: 수요일/6시 | G5: 1개월 | H5: 10 | I5: 1만 | J5: 45070 | L5: 45098 | N5: 45126 | O5: 45138 | P5: 45154 | R5: 45182 | T5: 45210 | V5: 45238 | X5: 45266 | Z5: 45294 | AB5: 45322 | AD5: 45350 | AF5: 45378
A6: 5 | B6: 김혜정 | C6: 010-5213-0895 | D6: 민요 | E6: 단체 | F6: 목요일 12시 | H6: 10 | I6: 1만 | J6: 45064 | L6: 45092 | N6: 45120 | P6: 45148 | R6: 45176 | T6: 45204 | V6: 45232 | X6: 45260 | Z6: 45288 | AB6: 45316 | AD6: 45344 | AF6: 45372
A7: 6 | B7: 최성옥 | C7: 010-8709-5262 | D7: 민요 | E7: 개인 | F7: 목요일/11시 | G7: 1개월 | H7: 15 | I7: 1만 | J7: 45064 | P7: 45141 | R7: 45169 | T7: 45197 | V7: 45225 | X7: 45253 | Z7: 45281 | AB7: 45309 | AD7: 45337 | AF7: 45365
A8: 7 | B8: 임하린 | C8: 010-4660-9812 | D8: 민요 | E8: 개인 | F8: 화요일 / 4시 | G8: 1개월 | H8: 15 | I8: 1만 | J8: 45062 | L8: 45090 | M8: 45130 | N8: 45118 | O8: 45161 | P8: 45146 | R8: 45174 | T8: 45202 | V8: 45230 | X8: 45258 | Z8: 45286 | AB8: 45314 | AD8: 45342 | AF8: 45370
A9: 8 | B9: 이옥형 | C9: 010-9868-6890 | D9: 장구 | E9: 단체 | F9: 수요일 3시 | G9: 3개월 | H9: 24 | J9: 45099 | L9: 45127 | N9: 45155 | P9: 45183 | R9: 45211 | T9: 45239 | V9: 45267 | X9: 45295 | Z9: 45323 | AB9: 45351 | AD9: 45379 | AF9: 45407
A10: 9 | B10: 고영숙 | C10: 010-2293-6349 | D10: 장구 | E10: 단체 | F10: 수요일/3시 | G10: 3개월 | H10: 15 | I10: 1만 | J10: 45113 | L10: 45141 | M10: 45132 | N10: 45169 | P10: 45197 | R10: 45225 | T10: 45253 | V10: 45281 | X10: 45309 | Z10: 45337 | AB10: 45365 | AD10: 45393 | AF10: 45421
A11: 10 | B11: 아름 다움 | C11: 010-2472-0002 | D11: 민/장구 | E11: 단체 | F11: 수요일 09/30분 | G11: 3개월 | H11: 60 | I11: 2만 | J11: 45138 | K11: 45111 | L11: 45169 | N11: 45197 | P11: 45211 | R11: 45239 | T11: 45267 | V11: 45295 | X11: 45323 | Z11: 45351 | AB11: 45379 | AD11: 45407 | AF11: 45435
A12: 11 | B12: 초빈 초연 | C12: 010-7481-9508 | D12: 민/장구 | E12: 단체 | F12: 수요일 09/30분 | G12: 3개월 | H12: 60 | I12: 2만 | J12: 45138 | K12: 45125 | L12: 45169 | N12: 45197 | P12: 45207 | R12: 45235 | T12: 45263 | V12: 45291 | X12: 45319 | Z12: 45347 | AB12: 45375 | AD12: 45403 | AF12: 45431
A13: 12 | B13: 신태희 | C13: 010-3942-4735 | D13: 민/장구 | E13: 단체 | F13: 수요일 3시4시 | G13: 1개월 | H13: 15 | I13: 1만 | J13: 45119 | L13: 7/19환불 10만
A14: 13 | B14: 배이준 | C14: 010-3719-0922 | D14: 민요 | E14: 개인 | F14: 주일 5시 | G14: 1개월 | H14: 15 | I14: 1만 | J14: 45123 | K14: 45123 | L14: 45151 | N14: 45179 | P14: 45207 | R14: 45235 | T14: 45263 | V14: 45291 | X14: 45319 | Z14: 45347 | AB14: 45375 | AD14: 45403 | AF14: 45431
A15: 14 | B15: 이옥형 | D15: 민요 | E15: 단체 | F15: 수요일 4시 | G15: 3개월 | H15: 10 | I15: 1만 | J15: 45126 | K15: 45126 | L15: 45154 | N15: 45182 | P15: 45210 | R15: 45238 | T15: 45266 | V15: 45294 | X15: 45322 | Z15: 45350 | AB15: 45378 | AD15: 45406 | AF15: 45434
A16: 15 | B16: 채린 | C16: 010-3383-1714 | D16: 민요 | E16: 개인 | F16: 주일 4시 | G16: 1개월 | H16: 15 | I16: 1만 | J16: 45142 | K16: 45142 | L16: 45173 | P16: 45210 | R16: 45238 | T16: 45266 | V16: 45294 | X16: 45322 | Z16: 45350 | AB16: 45378 | AD16: 45406 | AF16: 45434
A17: 16 | B17: 유승희 | C17: 010-2987-1850 | D17: 장구 | E17: 단체 | F17: 수요일 4시 | G17: 3개월 | H17: 24 | I17: 1만 | J17: 45140 | K17: 45146
A18: 17 | B18: 창민 | F18: 목요일/3시 | G18: 1개월 | H18: 15 | I18: 선물 | J18: 45142 | K18: 45142
A19: 18 | B19: 임하령 | C19: 010-3232-6065 | D19: 민요 | E19: 개인 | F19: 화요일 5시20붐 | G19: 1개월 | H19: 15 | I19: 선물 | J19: 45216 | K19: 45209 | L19: 45237 | N19: 45265
A20: 19 | B20: 민경임 | C20: 010-5269-3514 | D20: 민요 | E20: 개인 | F20: 월/목 오전 10시 | G20: 2개월 | H20: 80 | I20: 선물 | J20: 45239 | K20: 45239
A21: 20
A22: 21
A23: 22
A24: 23
A25: 24
A26: 25
A27: 26
A28: 27
A29: 28
A30: 29
A31: 30
A32: 31
... A58: 57

Sheet 23년
A1: 입금 | B1: =SUM(I3,K3,M3,O3,Q3,S3,U3,W3,Y3,AA3,AC3,AE3) -> 1468 | C1: 합창 | E1: NI | F1: =SUM(B1-D1,I5,K5,M5,O5,Q5,S5,U5,W5,Y5,AA5,AC5,AE5) -> 1468 | I1: =I3 -> 0 | K1: =K3 -> 0 | M1: =M3 -> 0 | O1: =O3 -> 0 | Q1: =Q3 -> 50 | S1: =S3 -> 102 | U1: =U3 -> 167 | W1: =W3 -> 236 | Y1: =Y3 -> 197 | AA1: =AA3 -> 212 | AC1: =AC3 -> 292 | AE1: =AE3 -> 212
H2: 1월 | I2: 입금 | J2: 2월 | K2: 입금 | L2: 3월 | M2: 입금 | N2: 4월 | O2: 입금 | P2: 5월 | Q2: 입금 | R2: 6월 | S2: 입금 | T2: 7월 | U2: 입금 | V2: 8월 | W2: 입금 | X2: 9월 | Y2: 입금 | Z2: 10월 | AA2: 입금 | AB2: 11월 | AC2: 입금 | AD2: 12월 | AE2: 입금 | AF2: 평균 | AG2: 수강인원
A3: 과목 | B3: 이름 | C3: 전화번호 | D3: 비고 | F3: =SUM(F22,F34) & "만" -> 229만 | I3: =SUM(I8:I30) -> 0 | K3: =SUM(K8:K30) -> 0 | M3: =SUM(M8:M30) -> 0 | O3: =SUM(O8:O30) -> 0 | Q3: =SUM(Q8:Q30) -> 50 | S3: =SUM(S8:S30) -> 102 | U3: =SUM(U8:U30) -> 167 | W3: =SUM(W8:W31) -> 236 | Y3: =SUM(Y8:Y30) -> 197 | AA3: =SUM(AA8:AA30) -> 212 | AC3: =SUM(AC8:AC32) -> 292 | AE3: =SUM(AE5,AE8,AE9,AE13:AE21,AE25:AE33) -> 212 | AF3: =AVERAGE(Q3,S3,U3,W3,Y3,AA3,AC3,AE3) -> 183.5 | AG3: =SUM(B22,B34) -> 18
A5: 투자 | B5: =SUM(I5,K5,M5,O5,Q5,S5,U5,W5,Y5,AA5,AC5,AE5) -> 0
A7: 외부
AF9: =SUM(I8:I9,K8:K9,M8:M9,O8:O9,Q8:Q9,S8:S9,U8:U9,W8:W9,Y8:Y9,AA8:AA9,AC8:AC9,AE8:AE9) -> 0
F10: =SUM(F8:F9) -> 0
A12: 어린이 개인
A13: 1 | B13: 임하린 | C13: 010-4660-9812 | D13: 어린이개인 | F13: 15 | P13: 16 | Q13: 15 | R13: 13 | S13: 15 | T13: 11 | U13: 15 | V13: 23 | W13: 15 | X13: 5 | Y13: 15 | Z13: 31 | AA13: 15 | AB13: 28 | AC13: 15 | AD13: 26 | AE13: 15
A14: 2 | B14: 이소영 | C14: 010-3492-7247 | D14: 어린이개인 | F14: 15 | R14: 18 | S14: 15 | T14: 16 | U14: 15 | V14: 13 | W14: 15 | X14: 10 | Y14: 15 | Z14: 8 | AA14: 15 | AB14: 5 | AC14: 15 | AD14: 3 | AE14: 15
A15: 3 | B15: 배이준 | C15: 010-3719-0922 | D15: 어린이개인 | F15: 15 | T15: 16 | U15: 15 | V15: 13 | W15: 15 | X15: 10 | Y15: 15 | Z15: 8 | AA15: 15 | AB15: 5 | AC15: 15 | AD15: 3 | AE15: 15
A16: 4,5 | B16: 아름,다움 | C16: 010-2472-0002 | D16: 어린이개인 | F16: 20 | T16: 31 | U16: 20 | V16: 31 | W16: 20 | X16: 28 | Y16: 20 | Z16: 12 | AA16: 20 | AB16: 9 | AC16: 20 | AD16: 7 | AE16: 20
A17: 6,7 | B17: 초빈,초연 | C17: 010-7481-9508 | D17: 어린이개인 | F17: 20 | T17: 31 | U17: 20 | V17: 31 | W17: 20 | X17: 28 | Y17: 20 | Z17: 8 | AA17: 20 | AB17: 5 | AC17: 20 | AD17: 31 | AE17: 20
A18: 8 | B18: 채린 | C18: 010-3383-1714 | D18: 어린이개인 | F18: 15 | V18: 4 | W18: 15 | X18: 4 | Y18: 15 | Z18: 11 | AA18: 15 | AB18: 8 | AC18: 15 | AD18: 6 | AE18: 15
A19: 9 | B19: 박창민 | C19: 010-3179-5478 | D19: 어린이개인 | F19: 15 | V19: 4 | W19: 15
A20: 10 | B20: 임하령 | C20: 010-3232-6065 | D20: 어린이개인 | F20: 15 | Z20: 17 | AA20: 15 | AB20: 7 | AC20: 15 | AD20: 5 | AE20: 15
A22: 총 | B22: 10 | F22: =SUM(F13:F21) -> 130
A24: 성인 개인
A25: 1 | B25: 공춘희 | C25: 010-9288-9750 | D25: 성인개인 | F25: 10 | P25: 24 | Q25: 10 | R25: 21 | S25: 10 | T25: 31 | U25: 10 | V25: 16 | W25: 10 | X25: 13 | Y25: 10 | Z25: 11 | AA25: 10 | AB25: 8 | AC25: 10 | AD25: 6 | AE25: 10
A26: 2 | B26: 김혜정 | C26: 010-5213-0895 | D26: 성인개인 | F26: 10 | P26: 18 | Q26: 10 | R26: 15 | S26: 10 | T26: 13 | U26: 10 | V26: 10 | W26: 10 | X26: 7 | Y26: 10 | Z26: 5 | AA26: 10 | AB26: 30 | AC26: 10 | AD26: 28 | AE26: 10
A27: 3 | B27: 최성옥 | C27: 010-8709-5262 | D27: 성인개인 | F27: 15 | P27: 18 | Q27: 15 | V27: 31 | W27: 15 | X27: 28 | Y27: 15 | Z27: 26 | AA27: 15 | AB27: 23 | AC27: 15 | AD27: 21 | AE27: 15
A28: 4 | B28: 고영숙 | C28: 010-2293-6349 | D28: 성인개인 | F28: 10 | R28: 17 | S28: 20 | T28: 15 | U28: 20 | V28: 12 | W28: 20 | X28: 9 | Y28: 20 | Z28: 7 | AA28: 20 | AB28: 4 | AC28: 20 | AD28: 2 | AE28: 20
A29: 5 | B29: 김다정 | C29: 010-8234-4080 | D29: 성인개인 | F29: 8 | R29: 18 | S29: 24 | T29: 16 | U29: 24 | V29: 13 | W29: 24 | X29: 10 | Y29: 24 | Z29: 8 | AA29: 24 | AB29: 5 | AC29: 24 | AD29: 3 | AE29: 24
A30: 6 | B30: 이옥형 | C30: 010-9868-6890 | D30: 성인개인 | F30: 18 | R30: 22 | S30: 8 | T30: 20 | U30: 18 | V30: 17 | W30: 18 | X30: 14 | Y30: 18 | Z30: 12 | AA30: 18 | AB30: 9 | AC30: 18 | AD30: 7 | AE30: 18
A31: 7 | B31: 유승희 | C31: 010-2987-1850 | D31: 성인개인 | F31: 8 | V31: 2 | W31: 24
A32: 8 | B32: 민경임 | C32: 010-5269-3514 | D32: 성인개인 | F32: 20 | AB32: 9 | AC32: 80
A34: 총 | B34: 8 | F34: =SUM(F25:F33) -> 99

Sheet 24년
A1: 입금 | B1: =SUM(I3,K3,M3,O3,Q3,S3,U3,W3,Y3,AA3,AC3,AE3) -> 5636.3 | C1: 합창 | D1: =SUM(AE30,AE134) -> 635 | E1: NI | F1: =SUM(B1-D1,I5,K5,M5,O5,Q5,S5,U5,W5,Y5,AA5,AC5,AE5) -> 4611.3 | I1: =I3 -> 390.2 | K1: =K3 -> 388.4 | M1: =M3 -> 472.6 | O1: =O3 -> 731 | Q1: =Q3 -> 526.4 | S1: =S3 -> 369.6 | U1: =U3 -> 317.8 | W1: =W3 -> 401.7 | Y1: =Y3 -> 577.4 | AA1: =AA3 -> 656.9 | AC1: =AC3 -> 505.3 | AE1: =AE3 -> 299
H2: 1월 | I2: 입금 | J2: 2월 | K2: 입금 | L2: 3월 | M2: 입금 | N2: 4월 | O2: 입금 | P2: 5월 | Q2: 입금 | R2: 6월 | S2: 입금 | T2: 7월 | U2: 입금 | V2: 8월 | W2: 입금 | X2: 9월 | Y2: 입금 | Z2: 10월 | AA2: 입금 | AB2: 11월 | AC2: 입금 | AD2: 12월 | AE2: 입금 | AF2: 평균 | AG2: 수강인원
A3: 과목 | B3: 이름 | C3: 전화번호 | D3: 카테고리 | F3: =SUM(F22,F30,F36,F47,F56) & "만" -> 361만 | I3: =SUM(I8:I143) -> 390.2 | K3: =SUM(K8:K143) -> 388.4 | M3: =SUM(M8:M143) -> 472.6 | O3: =SUM(O8:O143) -> 731 | Q3: =SUM(Q8:Q143) -> 526.4 | S3: =SUM(S8:S143) -> 369.6 | U3: =SUM(U8:U143) -> 317.8 | W3: =SUM(W8:W143) -> 401.7 | Y3: =SUM(Y8:Y143) -> 577.4 | AA3: =SUM(AA8:AA143) -> 656.9 | AC3: =SUM(AC8:AC143) -> 505.3 | AE3: =SUM(AE8:AE10,AE13:AE21,AE25:AE29,AE33:AE35,AE39:AE46,AE50:AE55,AE59:AE132) -> 299 | AF3: =AVERAGE(I3,K3,M3,O3,Q3,S3,U3,W3,Y3,AA3,AC3,AE3) -> 469.69167 | AG3: =SUM(B56,B47,B36,B30,B22) -> 28
A5: 투자 | B5: =SUM(I5,K5,M5,O5,Q5,S5,U5,W5,Y5,AA5,AC5,AE5) -> -390 | H5: 20 | I5: -50 | J5: 25 | K5: -20 | L5: 20 | M5: -30 | N5: 20 | O5: -20 | P5: 20 | Q5: -20 | X5: 13 | Y5: -150 | AB5: 16 | AC5: -100
A7: 외부
B8: 구로 | I8: =구로!D10 -> 3.2 | K8: =구로!E10 -> 6.4 | M8: =구로!F10 -> 31.6 | O8: =구로!G10 -> 23 | Q8: =구로!H10 -> 18.4 | S8: =구로!I10 -> 13.6 | U8: =구로!J10 -> 11.6 | W8: =구로!K10 -> 9.7 | Y8: =구로!L10 -> 11.6 | AA8: =구로!M10 -> 11.6 | AC8: =구로!N10 -> 0 | AE8: =구로!O10 -> 0
B9: 외부24년 | I9: =외부24년!L3 -> 16 | K9: =외부24년!O3 -> 2 | M9: =외부24년!R3 -> 26 | O9: =외부24년!U3 -> 72 | Q9: =외부24년!X3 -> 124 | S9: =외부24년!AA3 -> 4 | U9: =외부24년!AD3 -> 24.2 | W9: =외부24년!AG3 -> 4 | Y9: =외부24년!AJ3 -> 222.8 | AA9: =외부24년!AM3 -> 33.3 | AC9: =외부24년!AP3 -> 17.3 | AE9: =외부24년!AS3 -> 20 | AF9: 합계
B10: 악기대여 | I10: =악기24년!G3 -> 0 | K10: =악기24년!I3 -> 0 | M10: =악기24년!K3 -> 0 | O10: =악기24년!M3 -> 0 | Q10: =악기24년!O3 -> 3 | S10: =악기24년!Q3 -> 0 | U10: =악기24년!S3 -> 0 | W10: =악기24년!U3 -> 0 | Y10: =악기24년!W3 -> 0 | AA10: =악기24년!Y3 -> 0 | AC10: =악기24년!AA3 -> 0 | AE10: =악기24년!AC3 -> 0 | AF10: =SUM(I8:I10,K8:K10,M8:M10,O8:O10,Q8:Q10,S8:S10,U8:U10,W8:W10,Y8:Y10,AA8:AA10,AC8:AC10,AE8:AE10) -> 709.3
F11: =SUM(F8:F10) -> 0
A12: 어린이 개인
A13: 1 | B13: 임하린 | C13: 010-4660-9812 | D13: 어린이개인 | F13: 20 | H13: 24 | I13: 15 | J13: 23 | K13: 15 | L13: 23 | M13: 15 | N13: 23 | O13: 15 | P13: 23 | Q13: 15 | R13: 24 | S13: 15 | T13: 23 | U13: 15 | V13: 23 | W13: 15 | X13: 24 | Y13: 15 | Z13: 23 | AA13: 15 | AB13: 23 | AC13: 15 | AD13: 23 | AE13: 20
A14: 2 | B14: 배이준 | C14: 010-3719-0922 | D14: 어린이개인 | F14: 20 | H14: 20 | I14: 15 | J14: 25 | K14: 15 | L14: 5 | M14: 15 | N14: 15 | O14: 15 | R14: 1 | S14: 15 | V14: 15 | W14: 30 | Z14: 9 | AA14: 15 | AB14: 30 | AC14: 15 | AD14: 18 | AE14: 20
A15: 3 | B15: 변이서 | C15: 010-5599-2831 | D15: 어린이개인 | F15: 20 | J15: 29 | K15: 15 | N15: 1 | O15: 15 | P15: 21 | Q15: 30 | R15: 18 | S15: 15 | T15: 17 | U15: 15 | V15: 29 | W15: 20 | Z15: 12 | AA15: 15 | AB15: 12 | AC15: 15 | AD15: 12 | AE15: 20
A16: 4 | B16: 문도진 | C16: 010-3478-7942 | D16: 어린이개인 | F16: 20 | T16: 17 | U16: 15 | V16: 16 | W16: 15 | X16: 16 | Y16: 15 | Z16: 17 | AA16: 15 | AB16: 17 | AC16: 15 | AD16: 19 | AE16: 20
A17: 5 | B17: 박지윤 | C17: 010-7151-0507 | D17: 어린이개인 | F17: 20 | T17: 24 | U17: 15 | X17: 3 | Y17: 15 | Z17: 3 | AA17: 15 | AB17: 4 | AC17: 15 | AD17: 10 | AE17: 20
A18: 6 | B18: 민다현 | C18: 010-9795-9202 | D18: 어린이개인 | E18: 한은정 | F18: 20 | X18: 2 | Y18: 15 | Z18: 2 | AA18: 15 | AB18: 2 | AC18: 15 | AD18: 3 | AE18: 20
A19: 8 | B19: 김아인 | C19: 010-3128-3122 | D19: 어린이개인 | E19: 김포페이 | F19: 20 | Z19: 27 | AA19: 15 | AD19: 3 | AE19: 20
A20: 9 | B20: 서승아 | C20: 010-9434-6190 | D20: 어린이개인 | E20: 최유나 | F20: 20 | Z20: 31 | AA20: 15 | AB20: 28 | AC20: 15
A22: 총 | B22: 9 | F22: =SUM(F13:F21) -> 160
A24: 어린이 단체
A25: 1,2 | B25: 정승은,서은 | C25: 010-6329-6643 | D25: 어린이단체 | F25: 20 | T25: 23 | U25: 10 | X25: 5 | Y25: 10 | Z25: 29 | AA25: 10 | AB25: 25 | AC25: 10 | AD25: 2 | AE25: 20
A26: 3 | B26: 최유정,정원 | C26: 010-3342-6237 | D26: 어린이단체 | F26: 20 | Z26: 9 | AA26: 10 | AB26: 8 | AC26: 10
A27: 4 | B27: 조설 | C27: 010-4212-5917 | D27: 어린이단체 | F27: 10 | Z27: 31 | AA27: 5 | AB27: 2 | AC27: 5
A30: 총 | B30: 5 | F30: =SUM(F25:F29) -> 50 | AE30: =SUM(I25:I29,K25:K29,M25:M29,O25:O29,Q25:Q29,S25:S29,U25:U29,W25:W29,Y25:Y29,AA25:AA29,AC25:AC29,AE25:AE29) -> 90
A32: 성인 개인
A33: 1 | B33: 임미경 | C33: 010-2316-2915 | D33: 성인개인 | E33: 현금영수증 | F33: 20 | Z33: 4 | AA33: 20 | AB33: 4 | AC33: 20 | AD33: 5 | AE33: 20
A34: 2 | B34: 전문영 | C34: 010-2287-4572 | D34: 성인개인 | F34: 20 | Z34: 30 | AA34: 20 | AB34: 11 | AC34: 20
A36: 총 | B36: 2 | F36: =SUM(F33:F35) -> 40
A38: 성인 단체
A39: 1 | B39: 고영숙 | C39: 010-2293-6349 | D39: 성인단체 | F39: 8 | H39: 2 | I39: 24 | N39: 1 | O39: 24 | T39: 1 | U39: 24 | Z39: 2 | AA39: 24 | AD39: 02일 | AE39: 24
A40: 2 | B40: 김혜정 | C40: 010-5213-0895 | D40: 성인단체 | F40: 10 | H40: 25 | I40: 10 | J40: 22 | K40: 10 | L40: 21 | M40: 10 | N40: 1 | O40: 10 | P40: 1 | Q40: 10 | T40: 17 | U40: 10 | V40: 16 | W40: 10 | X40: 17 | Y40: 10 | Z40: 30 | AA40: 10 | AB40: 18 | AC40: 10
A41: 3 | B41: 김용 | C41: 010-5243-1591 | D41: 성인단체 | F41: 5 | H41: 2 | I41: 5 | J41: 1 | K41: 5 | L41: 1 | M41: 5 | N41: 1 | O41: 5 | P41: 1 | Q41: 5 | R41: 1 | S41: 5 | T41: 1 | U41: 5 | V41: 1 | W41: 5 | X41: 1 | Y41: 5 | Z41: 1 | AA41: 5 | AB41: 1 | AC41: 5 | AD41: 1 | AE41: 5
A42: 4 | B42: 신하린 | C42: 010-2607-4486 | D42: 성인단체 | F42: 10 | H42: 8 | I42: 15 | L42: 22 | M42: 10 | R42: 6 | S42: 10 | X42: 3 | Y42: 10 | Z42: 9 | AA42: 10 | AB42: 13 | AC42: 10
A43: 5 | B43: 윤분숙 | C43: 010-8227-5911 | D43: 성인단체 | F43: 8 | J43: 7 | K43: 8 | L43: 1 | M43: 8 | N43: 1 | O43: 8 | P43: 1 | Q43: 8 | R43: 3 | S43: 8 | T43: 1 | U43: 8 | V43: 1 | W43: 8 | X43: 1 | Y43: 8 | Z43: 1 | AA43: 8 | AB43: 1 | AC43: 8
A44: 6 | B44: 석경남 | C44: 010-5005-5581 | D44: 성인단체 | F44: 10 | L44: 13 | M44: 10 | N44: 3 | O44: 10 | P44: 8 | Q44: 10 | R44: 5 | S44: 10 | T44: 17 | U44: 10 | V44: 7 | W44: 10 | X44: 4 | Y44: 10 | Z44: 5 | AA44: 10 | AB44: 4 | AC44: 10 | AD44: 1 | AE44: 10
A45: 7 | B45: 박상혜 | C45: 010-7375-3111 | D45: 성인단체 | F45: 10 | L45: 20 | M45: 10 | N45: 20 | O45: 10 | P45: 20 | Q45: 10 | V45: 7 | W45: 10 | X45: 4 | Y45: 10 | Z45: 2 | AA45: 10 | AB45: 3 | AC45: 10 | AD45: 5 | AE45: 10
A47: 총 | B47: 7 | F47: =SUM(F39:F46) -> 61
A49: 심화
A50: 1 | B50: 임하린 | C50: 010-4660-9812 | D50: 어린이개인 | F50: 10 | J50: 20 | K50: 10 | L50: 19 | M50: 10 | N50: 19 | O50: 10 | T50: 23 | U50: 10 | V50: 23 | W50: 10 | X50: 24 | Y50: 10 | Z50: 23 | AA50: 10 | AB50: 23 | AC50: 10 | AD50: 23 | AE50: 10
A51: 2 | B51: 박지윤 | C51: 010-7151-0507 | D51: 어린이개인 | F51: 10 | Z51: 26 | AA51: 10 | AB51: 9 | AC51: 10 | AD51: 11 | AE51: 10
...

Sheet 25년
A1: 입금 | B1: =SUM(I3,K3,M3,O3,Q3,S3,U3,W3,Y3,AA3,AC3,AE3) -> 5156.7 | C1: 단체 | D1: =SUM(AE25) -> 340 | E1: NI | F1: =SUM(B1-D1) -> 4816.7 | I1: =I3 -> 418.9 | K1: =K3 -> 322.5 | M1: =M3 -> 452 | O1: =O3 -> 323.5 | Q1: =Q3 -> 549.7 | S1: =S3 -> 391 | U1: =U3 -> 410.1 | W1: =W3 -> 263.5 | Y1: =Y3 -> 439.7 | AA1: =AA3 -> 812.8 | AC1: =AC3 -> 518 | AE1: =AE3 -> 255
H2: 1월 | I2: 입금 | J2: 2월 | K2: 입금 | L2: 3월 | M2: 입금 | N2: 4월 | O2: 입금 | P2: 5월 | Q2: 입금 | R2: 6월 | S2: 입금 | T2: 7월 | U2: 입금 | V2: 8월 | W2: 입금 | X2: 9월 | Y2: 입금 | Z2: 10월 | AA2: 입금 | AB2: 11월 | AC2: 입금 | AD2: 12월 | AE2: 입금 | AG2: 평균 | AH2: 수강인원
A3: 과목 | B3: 이름 | C3: 전화번호 | D3: 카테고리 | E3: 추천경로 | F3: =SUM(F17,F25,F33,F48) & "만" -> 326만 | I3: =SUM(I6:I87) -> 418.9 | K3: =SUM(K6:K87) -> 322.5 | M3: =SUM(M6:M87) -> 452 | O3: =SUM(O6:O87) -> 323.5 | Q3: =SUM(Q6:Q87) -> 549.7 | S3: =SUM(S6:S87) -> 391 | U3: =SUM(U6:U87) -> 410.1 | W3: =SUM(W6:W87) -> 263.5 | Y3: =SUM(Y6:Y87) -> 439.7 | AA3: =SUM(AA6:AA87) -> 812.8 | AC3: =SUM(AC6:AC87) -> 518 | AE3: =SUM(AE6:AE7,AE10:AE16,AE20:AE24,AE36:AE47) -> 255 | AG3: =AVERAGE(I3,K3,M3,O3,Q3,S3,U3,W3,Y3,AA3,AC3,AE3) -> 429.725 | AH3: =SUM(B17,B25,B48) -> 26
A5: 외부
B6: 외부25년 | I6: =외부25년!K3 -> 125.9 | K6: =외부25년!N3 -> 49.5 | M6: =외부25년!Q3 -> 35 | O6: =외부25년!T3 -> 30.5 | Q6: =외부25년!W3 -> 246.7 | S6: =외부25년!Z3 -> 74 | U6: =외부25년!AC3 -> 117.1 | W6: =외부25년!AF3 -> 40.5 | Y6: =외부25년!AI3 -> 196.7 | AA6: =외부25년!AL3 -> 557.8 | AC6: =외부25년!AO3 -> 275 | AE6: =외부25년!AR3 -> 22
B7: 악기대여 | I7: =악기25년!G3 -> 0 | K7: =악기25년!I3 -> 0 | M7: =악기25년!K3 -> 0 | O7: =악기25년!M3 -> 0 | Q7: =악기25년!O3 -> 0 | S7: =악기25년!Q3 -> 0 | U7: =악기25년!S3 -> 0 | W7: =악기25년!U3 -> 0 | Y7: =악기25년!W3 -> 0 | AA7: =악기25년!Y3 -> 0 | AC7: =악기25년!AA3 -> 0 | AE7: =악기25년!AC3 -> 0
F8: =SUM(F6:F7) -> 0
A9: 어린이 개인
A10: 1 | B10: 배이준 | C10: 010-3719-0922 | D10: 어린이개인 | F10: 20 | J10: 10 | K10: 20 | L10: 13 | M10: 20 | N10: 15 | O10: 20 | P10: 21 | Q10: 20 | R10: 1 | S10: 30 | T10: 15 | U10: 10 | X10: 2 | Y10: 20 | Z10: 25 | AA10: 20 | AB10: 20 | AC10: 20
A11: 2 | B11: 변이서 | C11: 010-5599-2831 | D11: 어린이개인 | F11: 20 | H11: 10 | I11: 20 | J11: 12 | K11: 20 | L11: 11 | M11: 20 | N11: 15 | O11: 20 | P11: 13 | Q11: 20 | R11: 11 | S11: 20 | T11: 20 | U11: 20 | V11: 18 | W11: 20 | X11: 18 | Y11: 20 | Z11: 15 | AA11: 20 | AB11: 25 | AC11: 20 | AD11: 28 | AE11: 20
A12: 3 | B12: 문도진 | C12: 010-3478-7942 | D12: 어린이개인 | F12: 20 | H12: 18 | I12: 20 | J12: 17 | K12: 20 | L12: 17 | M12: 20 | N12: 17 | O12: 20 | P12: 17 | Q12: 20 | R12: 17 | S12: 20 | T12: 17 | U12: 20 | V12: 20 | W12: 20 | X12: 20 | Y12: 20 | Z12: 20 | AA12: 20 | AB12: 20 | AC12: 20 | AD12: 20 | AE12: 20
A13: 4 | B13: 고나은 | C13: 010-4552-3662 | D13: 어린이개인 | E13: 현금영수증 | F13: 20 | L13: 28 | M13: 20 | N13: 28 | O13: 20 | P13: 26 | Q13: 20 | T13: 7 | U13: 20 | V13: 28 | W13: 20 | X13: 16 | Y13: 20 | Z13: 6 | AA13: 20 | AB13: 10 | AC13: 20 | AD13: 8 | AE13: 20
A14: 5 | B14: 최재인 | C14: 010-4046-5528 | D14: 어린이개인 | F14: 30 | P14: 2 | Q14: 20 | R14: 6 | S14: 20 | T14: 7 | U14: 10 | V14: 10 | W14: 10 | X14: 9 | Y14: 10 | Z14: 14 | AA14: 30 | AB14: 11 | AC14: 30 | AD14: 11 | AE14: 30
A15: 6 | B15: 강서은 | C15: 010-4230-0069 | D15: 어린이개인 | F15: 20 | Z15: 28 | AA15: 10 | AD15: 3 | AE15: 20
A17: 총 | B17: 6 | F17: =SUM(F10:F16) -> 130
A19: 어린이 단체
A20: 1 | B20: 민다현 | C20: 010-9795-9202 | D20: 어린이단체 | E20: 한은정 | F20: 10 | H20: 6 | I20: 20 | J20: 3 | K20: 20 | L20: 11 | M20: 10 | N20: 4 | O20: 10 | P20: 7 | Q20: 10 | R20: 8 | S20: 10 | T20: 1 | U20: 10 | V20: 6 | W20: 10 | X20: 5 | Y20: 10 | Z20: 10 | AA20: 10 | AB20: 5 | AC20: 10 | AD20: 5 | AE20: 10
A21: 2,3 | B21: 정승은,서은 | C21: 010-6329-6643 | D21: 어린이단체 | E21: 이윤실 | F21: 20 | L21: 11 | M21: 20 | N21: 23 | O21: 20 | P21: 25 | Q21: 20 | T21: 16 | U21: 20 | V21: 5 | W21: 20 | X21: 1 | Y21: 20 | Z21: 1 | AA21: 20 | AB21: 18 | AC21: 20 | AD21: 8 | AE21: 20
A22: 4 | B22: 서승아 | C22: 010-9434-6190 | D22: 어린이단체 | F22: 10 | AB22: 19 | AC22: 10 | AD22: 9 | AE22: 10
A23: 5,6 | B23: 이율,이윤 | C23: 010-2718-0838 | D23: 어린이단체 | F23: 0
A25: 총 | B25: 6 | F25: =SUM(F20:F24) -> 40 | AE25: =SUM(I20:I24,K20:K24,M20:M24,O20:O24,Q20:Q24,S20:S24,U20:U24,W20:W24,Y20:Y24,AA20:AA24,AC20:AC24,AE20:AE24) -> 340
A27: 성인 개인
A28: 1 | B28: 고영숙 | C28: 010-2293-6349 | D28: 성인개인 | F28: 10 | N28: 11 | O28: 10 | P28: 30 | Q28: 10 | R28: 4 | S28: 10 | T28: 3 | U28: 10 | V28: 1 | W28: 10 | X28: 1 | Y28: 10 | Z28: 1 | AA28: 10 | AB28: 6 | AC28: 10 | AD28: 5 | AE28: 10
A29: 2 | B29: 임미경 | C29: 010-2316-2915 | D29: 성인개인 | E29: 현금영수증 | F29: 20 | H29: 7 | I29: 20 | J29: 4 | K29: 20 | L29: 10 | M29: 20 | N29: 15 | O29: 20 | P29: 12 | Q29: 20 | R29: 11 | S29: 20 | T29: 14 | U29: 20 | V29: 12 | W29: 20 | X29: 15 | Y29: 20 | AB29: 10 | AC29: 20 | AD29: 15 | AE29: 20
A30: 3 | B30: 조현자 | C30: 010-5410-9767 | D30: 성인개인 | F30: 20 | AD30: 1 | AE30: 20
A31: 4 | B31: 전수연 | C31: 010-7746-9181 | D31: 성인개인 | F31: 15 | AD31: 12 | AE31: 15
A33: 총 | B33: 9 | F33: =SUM(F28:F32) -> 65
A35: 성인 단체
A36: 1 | B36: 고영숙 | C36: 010-2293-6349 | D36: 성인단체 | F36: 8 | L36: 4 | M36: 24 | R36: 4 | S36: 24 | Z36: 1 | AA36: 24
A37: 2 | B37: 김용 | C37: 010-5243-1591 | D37: 성인단체 | F37: 5 | H37: 1 | I37: 5 | J37: 1 | K37: 5 | L37: 1 | M37: 5 | N37: 1 | O37: 5 | P37: 1 | Q37: 5 | R37: 1 | S37: 5 | T37: 1 | U37: 5 | V37: 1 | W37: 5 | X37: 1 | Y37: 5 | AB37: 1 | AC37: 5 | AD37: 1 | AE37: 5
A38: 3 | B38: 윤분숙 | C38: 010-8227-5911 | D38: 성인단체 | F38: 8 | H38: 1 | I38: 8 | J38: 1 | K38: 8 | L38: 1 | M38: 8 | N38: 1 | O38: 8 | P38: 1 | Q38: 8 | R38: 1 | S38: 8 | T38: 1 | U38: 8 | V38: 1 | W38: 8 | X38: 1 | Y38: 8 | Z38: 1 | AA38: 8 | AB38: 1 | AC38: 8 | AD38: 1 | AE38: 8
A39: 4 | B39: 석경남 | C39: 010-5005-5581 | D39: 성인단체 | F39: 10 | H39: 01일 | I39: 10 | J39: 5 | K39: 10 | L39: 27 | M39: 10 | N39: 31 | O39: 10 | P39: 1 | Q39: 10 | R39: 1 | S39: 10 | T39: 1 | U39: 10 | V39: 27 | W39: 10 | X39: 30 | Y39: 10 | Z39: 29 | AA39: 10 | AD39: 1 | AE39: 10
A40: 5 | B40: 박상혜 | C40: 010-7375-3111 | D40: 성인단체 | F40: 10 | H40: 8 | I40: 10 | J40: 5 | K40: 10 | L40: 5 | M40: 10 | N40: 4 | O40: 10 | P40: 10 | Q40: 10 | R40: 7 | S40: 10 | T40: 3 | U40: 10 | V40: 6 | W40: 10 | X40: 5 | Y40: 10 | Z40: 14 | AA40: 10 | AB40: 14 | AC40: 10 | AD40: 1 | AE40: 10
A41: 6 | B41: 유영순 | C41: 010-5284-4457 | D41: 성인단체 | F41: 10 | H41: 1 | I41: 10 | J41: 2 | K41: 10 | L41: 4 | M41: 10 | N41: 1 | O41: 10 | P41: 1 | Q41: 10 | R41: 1 | S41: 10 | T41: 1 | U41: 10 | V41: 1 | W41: 10 | X41: 1 | Y41: 10 | Z41: 1 | AA41: 10 | AB41: 2 | AC41: 10 | AD41: 1 | AE41: 10
A42: 7 | B42: 이말진 | C42: 010-9873-7764 | D42: 성인단체 | F42: 10 | H42: 2 | I42: 10 | J42: 5 | K42: 10 | L42: 4 | M42: 10 | N42: 2 | O42: 10 | P42: 5 | Q42: 10 | R42: 4 | S42: 10 | T42: 2 | U42: 10 | V42: 6 | W42: 10 | X42: 1 | Y42: 10 | Z42: 2 | AA42: 10 | AB42: 1 | AC42: 10 | AD42: 1 | AE42: 10
A43: 9 | B43: 김혜정 | C43: 010-5213-0895 | D43: 성인단체 | F43: 10 | L43: 14 | M43: 10 | N43: 14 | O43: 10 | P43: 14 | Q43: 10 | R43: 14 | S43: 10 | T43: 14 | U43: 20 | V43: 13 | W43: 20 | X43: 14 | Y43: 10 | Z43: 14 | AA43: 10 | AB43: 16 | AC43: 10
A44: 10 | B44: 박마리나 | C44: 010-5763-6356 | D44: 성인단체 | F44: 10 | R44: 28 | S44: 10 | T44: 19 | U44: 10 | AB44: 24 | AC44: 10 | AD44: 22 | AE44: 10
A45: 11 | B45: 홍유정 | C45: 010-3144-7294 | D45: 성인단체 | F45: 10 | Z45: 13 | AA45: 13 | AD45: 5 | AE45: 10
A46: 14 | B46: 오윤분 | C46: 010-5377-1304 | D46: 성인단체 | AD46: 24 | AE46: 10
A48: 총 | B48: 14 | F48: =SUM(F36:F47) -> 91
...

Sheet 26년
A1: 입금 | B1: =SUM(I3,K3,M3,O3,Q3,S3,U3,W3,Y3,AA3,AC3,AE3) -> 1551 | C1: 단체 | D1: =SUM(AE31) -> 190 | E1: NI | F1: =SUM(B1-D1) -> 1361 | I1: =I3 -> 498 | K1: =K3 -> 416 | M1: =M3 -> 572 | O1: =O3 -> 65 | Q1: =Q3 -> 0 | S1: =S3 -> 0 | U1: =U3 -> 0 | W1: =W3 -> 0 | Y1: =Y3 -> 0 | AA1: =AA3 -> 0 | AC1: =AC3 -> 0 | AE1: =AE3 -> 0
H2: 1월 | I2: 입금 | J2: 2월 | K2: 입금 | L2: 3월 | M2: 입금 | N2: 4월 | O2: 입금 | P2: 5월 | Q2: 입금 | R2: 6월 | S2: 입금 | T2: 7월 | U2: 입금 | V2: 8월 | W2: 입금 | X2: 9월 | Y2: 입금 | Z2: 10월 | AA2: 입금 | AB2: 11월 | AC2: 입금 | AD2: 12월 | AE2: 입금 | AG2: 평균 | AH2: 수강인원
A3: 과목 | B3: 이름 | C3: 전화번호 | D3: 카테고리 | E3: 추천경로 | F3: =SUM(F5,F18,F31,F59,F44) & "만" -> 553만 | I3: =SUM(I5:I101) -> 498 | K3: =SUM(K5:K101) -> 416 | M3: =SUM(M5:M101) -> 572 | O3: =SUM(O5:O101) -> 65 | Q3: =SUM(Q5:Q101) -> 0 | S3: =SUM(S5:S101) -> 0 | U3: =SUM(U5:U101) -> 0 | W3: =SUM(W5:W101) -> 0 | Y3: =SUM(Y5:Y101) -> 0 | AA3: =SUM(AA5:AA101) -> 0 | AC3: =SUM(AC5:AC101) -> 0 | AE3: =SUM(AE5:AE5,AE8:AE17,AE21:AE30,AE34:AE43,AE47:AE58) -> 0 | AG3: =AVERAGE(I3,K3,M3,O3,Q3,S3,U3,W3,Y3,AA3,AC3,AE3) -> 129.25 | AH3: =SUM(B18,B31,B44,B59) -> 40
A4: 외부
B5: 외부26년 | I5: =외부26년!L3 -> 196 | K5: =외부26년!O3 -> 103 | M5: =외부26년!R3 -> 57 | O5: =외부26년!U3 -> 0 | Q5: =외부26년!X3 -> 0 | S5: =외부26년!AA3 -> 0 | U5: =외부26년!AD3 -> 0 | W5: =외부26년!AG3 -> 0 | Y5: =외부26년!AJ3 -> 0 | AA5: =외부26년!AM3 -> 0 | AC5: =외부26년!AP3 -> 0 | AE5: =외부26년!AS3 -> 0
A7: 어린이 개인
A8: 1 | B8: 배이준 | C8: 010-3719-0922 | D8: 어린이개인 | F8: 20 | L8: 4 | M8: 20
A9: 2 | B9: 변이서 | C9: 010-5599-2831 | D9: 어린이개인 | F9: 20 | L9: 24 | M9: 20
A10: 3 | B10: 문도진 | C10: 010-3478-7942 | D10: 어린이개인 | F10: 20 | H10: 20 | I10: 20 | J10: 20 | K10: 20 | L10: 20 | M10: 20
A11: 4 | B11: 고나은 | C11: 010-4552-3662 | D11: 어린이개인 | E11: 현금영수증 | F11: 20 | H11: 8 | I11: 20 | J11: 9 | K11: 20 | L11: 17 | M11: 20
A12: 5 | B12: 최재인 | C12: 010-4046-5528 | D12: 어린이개인 | F12: 30 | H12: 20 | I12: 30 | J12: 12 | K12: 30 | L12: 23 | M12: 30
A13: 6 | B13: 강서은 | C13: 010-4230-0069 | D13: 어린이개인 | E13: 강창엽 | F13: 20 | H13: 2 | I13: 20 | J13: 4 | K13: 20 | L13: 3 | M13: 20 | N13: 1 | O13: 20
A14: 7 | B14: 이하빈 | C14: 010-5586-8174 | D14: 어린이개인 | F14: 30 | L14: 5 | M14: 20
A15: 8 | B15: 민다현 | C15: 010-9795-9202 | D15: 어린이개인 | E15: 한은정 | F15: 20 | H15: 5 | I15: 10 | J15: 5 | K15: 10 | L15: 6 | M15: 10
A16: 9 | B16: 서승아 | C16: 010-9434-6190 | D16: 어린이개인 | F16: 20 | H16: 13 | I16: 10 | J16: 11 | K16: 10 | L16: 17 | M16: 10
A18: 총 | B18: 9 | F18: =SUM(F8:F17) -> 200
A20: 어린이 단체
A21: 1,2 | B21: 정승은,서은 | C21: 010-6329-6643 | D21: 어린이단체 | E21: 이윤실 | F21: 20 | H21: 23 | I21: 20 | J21: 27 | K21: 20 | L21: 1 | M21: 20
A22: 3 | B22: 박하늘 | C22: 010-2116-0516 | D22: 어린이단체 | F22: 10 | H22: 2 | I22: 10 | J22: 2 | K22: 10 | L22: 15 | M22: 10
A23: 4 | B23: 장수민 | C23: 010-3993-5005 | D23: 어린이단체 | F23: 10 | J23: 24 | K23: 10 | L23: 31 | M23: 10
A24: 5,6 | B24: 최시월,소월 | C24: 010-3014-5953 | D24: 어린이단체 | E24: 카드 | F24: 20 | J24: 27 | K24: 20 | L24: 31 | M24: 20
A25: 7 | B25: 조영주 | C25: 010-9976-0486 | D25: 어린이단체 | E25: 네이버 | F25: 10 | L25: 10 | M25: 10
A26: 8 | B26: 이채원 | C26: 010-2872-9713 | D26: 어린이단체 | E26: 민다현 | F26: 10 | L26: 25 | M26: 10
A27: 9 | B27: 강이연 | C27: 010-9048-7358 | D27: 어린이단체 | F27: 10 | L27: 31 | M27: 10
A28: 10 | B28: 정서빈 | C28: 010-6502-8261 | D28: 어린이단체 | F28: 10 | L28: 31 | M28: 10
A30: 11,12 | B30: 이율,이윤 | C30: 010-2718-0838 | D30: 어린이단체 | F30: 0
A31: 총 | B31: 12 | F31: =SUM(F21:F30) -> 100 | AE31: =SUM(I21:I30,K21:K30,M21:M30,O21:O30,Q21:Q30,S21:S30,U21:U30,W21:W30,Y21:Y30,AA21:AA30,AC21:AC30,AE21:AE30) -> 190
A33: 성인 개인
A34: 1 | B34: 고영숙 | C34: 010-2293-6349 | D34: 성인개인 | F34: 10 | H34: 5 | I34: 10 | J34: 5 | K34: 10 | L34: 6 | M34: 10
A35: 2 | B35: 이말진 | C35: 010-9873-7764 | D35: 성인개인 | F35: 10 | H35: 8 | I35: 10 | J35: 2 | K35: 20 | L35: 4 | M35: 10 | N35: 1 | O35: 10
A36: 3 | B36: 임미경 | C36: 010-2316-2915 | D36: 성인개인 | E36: 현금영수증 | F36: 20 | H36: 14 | I36: 20 | J36: 10 | K36: 20 | L36: 16 | M36: 20
A37: 4 | B37: 박마리나 | C37: 010-5763-6356 | D37: 성인개인 | F37: 20 | L37: 24 | M37: 20
A38: 5 | B38: 홍유정 | C38: 010-3144-7294 | D38: 성인개인 | F38: 20 | H38: 31 | I38: 20 | L38: 14 | M38: 20
A39: 6 | B39: 조현자 | C39: 010-5410-9767 | D39: 성인개인 | F39: 20 | H39: 10 | I39: 20 | J39: 12 | K39: 20 | L39: 12 | M39: 20
A40: 7 | B40: 전수연 | C40: 010-7746-9181 | D40: 성인개인 | F40: 20 | H40: 14 | I40: 15 | J40: 25 | K40: 20 | L40: 25 | M40: 20
A41: 8 | B41: 김다정 | C41: 010-8234-4080 | D41: 성인개인 | F41: 10 | J41: 11 | K41: 10 | L41: 11 | M41: 10
A42: 9 | B42: 김규리 | C42: 010-3542-7808 | D42: 성인개인 | F42: 20
A44: 총 | B44: 9 | F44: =SUM(F34:F43) -> 150
A46: 성인 단체
B47: 고영숙 | C47: 010-2293-6349 | D47: 성인단체 | F47: 8 | H47: 5 | I47: 24
...

Sheet 외부24년
A1: 총 입금 | B1: =SUM(K3,N3,Q3,T3,W3,Z3,AC3,AF3,AI3,AL3,AO3,AR3) -> 765.6 | C1: 총 수입 | D1: =SUM(L3,O3,R3,U3,X3,AA3,AD3,AG3,AJ3,AM3,AP3,AS3) -> 565.6
G2: 수강료 | H2: 수입 | I2: 비고 | J2: 1월 | K2: 입금 | L2: 수입 | M2: 2월 | N2: 입금 | O2: 수입 | P2: 3월 | Q2: 입금 | R2: 수입 | S2: 4월 | T2: 입금 | U2: 수입 | V2: 5월 | W2: 입금 | X2: 수입 | Y2: 6월 | Z2: 입금 | AA2: 수입 | AB2: 7월 | AC2: 입금 | AD2: 수입 | AE2: 8월 | AF2: 입금 | AG2: 수입 | AH2: 9월 | AI2: 입금 | AJ2: 수입 | AK2: 10월 | AL2: 입금 | AM2: 수입 | AN2: 11월 | AO2: 입금 | AP2: 수입 | AQ2: 12월 | AR2: 입금 | AS2: 수입
